[2025-07-12 01:09:09] üìÅ Directory already exists: all excels
[2025-07-12 01:09:09] üìÅ Directory already exists: all excels
[2025-07-12 01:09:09] üìÅ Directory already exists: logs/screenshots
[2025-07-12 01:09:09] üìÅ Directory already exists: all resumes/default
[2025-07-12 01:09:09] üìÅ Directory already exists: all resumes/temp
[2025-07-12 01:09:09] IF YOU HAVE MORE THAN 10 TABS OPENED, PLEASE CLOSE OR BOOKMARK THEM!
[2025-07-12 01:09:09] SAFE MODE: Using guest profile, no history saved!
[2025-07-12 01:18:26] üìÅ Directory already exists: all excels
[2025-07-12 01:18:26] üìÅ Directory already exists: all excels
[2025-07-12 01:18:26] üìÅ Directory already exists: logs/screenshots
[2025-07-12 01:18:26] üìÅ Directory already exists: all resumes/default
[2025-07-12 01:18:26] üìÅ Directory already exists: all resumes/temp
[2025-07-12 01:18:26] IF YOU HAVE MORE THAN 10 TABS OPENED, PLEASE CLOSE OR BOOKMARK THEM!
[2025-07-12 01:18:26] SAFE MODE: Using guest profile, no history saved!
[2025-07-12 01:24:58] üìÅ Directory already exists: all excels
[2025-07-12 01:24:58] üìÅ Directory already exists: all excels
[2025-07-12 01:24:58] üìÅ Directory already exists: logs/screenshots
[2025-07-12 01:24:58] üìÅ Directory already exists: all resumes/default
[2025-07-12 01:24:58] üìÅ Directory already exists: all resumes/temp
[2025-07-12 01:24:58] IF YOU HAVE MORE THAN 10 TABS OPENED, PLEASE CLOSE OR BOOKMARK THEM!
[2025-07-12 01:24:58] SAFE MODE: Using guest profile, no history saved!
[2025-07-12 01:27:24] üìÅ Directory already exists: all excels
[2025-07-12 01:27:24] üìÅ Directory already exists: all excels
[2025-07-12 01:27:24] üìÅ Directory already exists: logs/screenshots
[2025-07-12 01:27:24] üìÅ Directory already exists: all resumes/default
[2025-07-12 01:27:24] üìÅ Directory already exists: all resumes/temp
[2025-07-12 01:27:24] IF YOU HAVE MORE THAN 10 TABS OPENED, PLEASE CLOSE OR BOOKMARK THEM!
[2025-07-12 01:27:24] SAFE MODE: Using guest profile, no history saved!
[2025-07-12 01:30:30] üìÅ Directory already exists: all excels
[2025-07-12 01:30:30] üìÅ Directory already exists: all excels
[2025-07-12 01:30:30] üìÅ Directory already exists: logs/screenshots
[2025-07-12 01:30:30] üìÅ Directory already exists: all resumes/default
[2025-07-12 01:30:30] üìÅ Directory already exists: all resumes/temp
[2025-07-12 01:30:30] IF YOU HAVE MORE THAN 10 TABS OPENED, PLEASE CLOSE OR BOOKMARK THEM!
[2025-07-12 01:30:30] SAFE MODE: Using guest profile, no history saved!
[2025-07-12 01:32:24] üìÅ Directory already exists: all excels
[2025-07-12 01:32:24] üìÅ Directory already exists: all excels
[2025-07-12 01:32:24] üìÅ Directory already exists: logs/screenshots
[2025-07-12 01:32:24] üìÅ Directory already exists: all resumes/default
[2025-07-12 01:32:24] üìÅ Directory already exists: all resumes/temp
[2025-07-12 01:32:24] IF YOU HAVE MORE THAN 10 TABS OPENED, PLEASE CLOSE OR BOOKMARK THEM!
[2025-07-12 01:32:24] SAFE MODE: Using guest profile, no history saved!
[2025-07-12 01:39:40] üìÅ Directory already exists: all excels
[2025-07-12 01:39:40] üìÅ Directory already exists: all excels
[2025-07-12 01:39:40] üìÅ Directory already exists: logs/screenshots
[2025-07-12 01:39:40] üìÅ Directory already exists: all resumes/default
[2025-07-12 01:39:40] üìÅ Directory already exists: all resumes/temp
[2025-07-12 01:39:40] IF YOU HAVE MORE THAN 10 TABS OPENED, PLEASE CLOSE OR BOOKMARK THEM!
[2025-07-12 01:39:40] SAFE MODE: Using guest profile, no history saved!
[2025-07-12 01:39:44] Critical error in main:
[2025-07-12 01:39:44] [ERROR] Invalid input for us_citizenship. Expecting a value from ['U.S. Citizen/Permanent Resident', 'Non-citizen allowed to work for any employer', 'Non-citizen allowed to work for current employer', 'Non-citizen seeking work authorization', 'Canadian Citizen/Permanent Resident', 'Other'], not Yes!: In main
Traceback (most recent call last):
  File "/home/wagle/garbageGold/app/linkedinBot/linkedinRun.py", line 802, in linkedinMain
    validate_config()
    ~~~~~~~~~~~~~~~^^
  File "/home/wagle/garbageGold/app/linkedinBot/utils/validator.py", line 201, in validate_config
    validate_questions()
    ~~~~~~~~~~~~~~~~~~^^
  File "/home/wagle/garbageGold/app/linkedinBot/utils/validator.py", line 72, in validate_questions
    check_string(us_citizenship, "us_citizenship", ["U.S. Citizen/Permanent Resident", "Non-citizen allowed to work for any employer", "Non-citizen allowed to work for current employer", "Non-citizen seeking work authorization", "Canadian Citizen/Permanent Resident", "Other"])
    ~~~~~~~~~~~~^^^^^^^^^^^^^^^^^^^^^^^^^^^^^^^^^^^^^^^^^^^^^^^^^^^^^^^^^^^^^^^^^^^^^^^^^^^^^^^^^^^^^^^^^^^^^^^^^^^^^^^^^^^^^^^^^^^^^^^^^^^^^^^^^^^^^^^^^^^^^^^^^^^^^^^^^^^^^^^^^^^^^^^^^^^^^^^^^^^^^^^^^^^^^^^^^^^^^^^^^^^^^^^^^^^^^^^^^^^^^^^^^^^^^^^^^^^^^^^^^^^^^^^^^^^^^^^^^^^^^
  File "/home/wagle/garbageGold/app/linkedinBot/utils/validator.py", line 16, in check_string
    if len(options) > 0 and var not in options: raise ValueError(f'Invalid input for {var_name}. Expecting a value from {options}, not {var}!')
                                                ^^^^^^^^^^^^^^^^^^^^^^^^^^^^^^^^^^^^^^^^^^^^^^^^^^^^^^^^^^^^^^^^^^^^^^^^^^^^^^^^^^^^^^^^^^^^^^^
ValueError: Invalid input for us_citizenship. Expecting a value from ['U.S. Citizen/Permanent Resident', 'Non-citizen allowed to work for any employer', 'Non-citizen allowed to work for current employer', 'Non-citizen seeking work authorization', 'Canadian Citizen/Permanent Resident', 'Other'], not Yes!

[2025-07-12 01:39:59] 
============================================================
[2025-07-12 01:39:59] FINAL STATISTICS
[2025-07-12 01:39:59] ============================================================
[2025-07-12 01:39:59] Total runs:                     1
[2025-07-12 01:39:59] Jobs Easy Applied:              0
[2025-07-12 01:39:59] External job links collected:   0
[2025-07-12 01:39:59]                               ----------
[2025-07-12 01:39:59] Total applied or collected:     0
[2025-07-12 01:39:59] 
Failed jobs:                    0
[2025-07-12 01:39:59] Irrelevant jobs skipped:        0
[2025-07-12 01:39:59] 
Keep up with the progress. You got this.

Best regards,
Sai Vignesh Golla
https://www.linkedin.com/in/saivigneshgolla/
[2025-07-12 01:48:48] üìÅ Directory already exists: all excels
[2025-07-12 01:48:48] üìÅ Directory already exists: all excels
[2025-07-12 01:48:48] üìÅ Directory already exists: logs/screenshots
[2025-07-12 01:48:48] üìÅ Directory already exists: all resumes/default
[2025-07-12 01:48:48] üìÅ Directory already exists: all resumes/temp
[2025-07-12 01:48:48] IF YOU HAVE MORE THAN 10 TABS OPENED, PLEASE CLOSE OR BOOKMARK THEM!
[2025-07-12 01:48:48] SAFE MODE: Using guest profile, no history saved!
[2025-07-12 01:48:54] Critical error in main:
[2025-07-12 01:48:54] [ERROR] Invalid input for us_citizenship. Expecting a value from ['U.S. Citizen/Permanent Resident', 'Non-citizen allowed to work for any employer', 'Non-citizen allowed to work for current employer', 'Non-citizen seeking work authorization', 'Canadian Citizen/Permanent Resident', 'Other'], not Yes!: In main
Traceback (most recent call last):
  File "/home/wagle/garbageGold/app/linkedinBot/linkedinRun.py", line 802, in linkedinMain
    validate_config()
    ~~~~~~~~~~~~~~~^^
  File "/home/wagle/garbageGold/app/linkedinBot/utils/validator.py", line 201, in validate_config
    validate_questions()
    ~~~~~~~~~~~~~~~~~~^^
  File "/home/wagle/garbageGold/app/linkedinBot/utils/validator.py", line 72, in validate_questions
    check_string(us_citizenship, "us_citizenship", ["U.S. Citizen/Permanent Resident", "Non-citizen allowed to work for any employer", "Non-citizen allowed to work for current employer", "Non-citizen seeking work authorization", "Canadian Citizen/Permanent Resident", "Other"])
    ~~~~~~~~~~~~^^^^^^^^^^^^^^^^^^^^^^^^^^^^^^^^^^^^^^^^^^^^^^^^^^^^^^^^^^^^^^^^^^^^^^^^^^^^^^^^^^^^^^^^^^^^^^^^^^^^^^^^^^^^^^^^^^^^^^^^^^^^^^^^^^^^^^^^^^^^^^^^^^^^^^^^^^^^^^^^^^^^^^^^^^^^^^^^^^^^^^^^^^^^^^^^^^^^^^^^^^^^^^^^^^^^^^^^^^^^^^^^^^^^^^^^^^^^^^^^^^^^^^^^^^^^^^^^^^^^^
  File "/home/wagle/garbageGold/app/linkedinBot/utils/validator.py", line 16, in check_string
    if len(options) > 0 and var not in options: raise ValueError(f'Invalid input for {var_name}. Expecting a value from {options}, not {var}!')
                                                ^^^^^^^^^^^^^^^^^^^^^^^^^^^^^^^^^^^^^^^^^^^^^^^^^^^^^^^^^^^^^^^^^^^^^^^^^^^^^^^^^^^^^^^^^^^^^^^
ValueError: Invalid input for us_citizenship. Expecting a value from ['U.S. Citizen/Permanent Resident', 'Non-citizen allowed to work for any employer', 'Non-citizen allowed to work for current employer', 'Non-citizen seeking work authorization', 'Canadian Citizen/Permanent Resident', 'Other'], not Yes!

[2025-07-12 01:48:57] 
============================================================
[2025-07-12 01:48:57] FINAL STATISTICS
[2025-07-12 01:48:57] ============================================================
[2025-07-12 01:48:57] Total runs:                     1
[2025-07-12 01:48:57] Jobs Easy Applied:              0
[2025-07-12 01:48:57] External job links collected:   0
[2025-07-12 01:48:57]                               ----------
[2025-07-12 01:48:57] Total applied or collected:     0
[2025-07-12 01:48:57] 
Failed jobs:                    0
[2025-07-12 01:48:57] Irrelevant jobs skipped:        0
[2025-07-12 01:48:57] 
The road to success and the road to failure are almost exactly the same. The difference is perseverance.

Best regards,
Sai Vignesh Golla
https://www.linkedin.com/in/saivigneshgolla/
[2025-07-12 01:51:26] üìÅ Directory already exists: all excels
[2025-07-12 01:51:26] üìÅ Directory already exists: all excels
[2025-07-12 01:51:26] üìÅ Directory already exists: logs/screenshots
[2025-07-12 01:51:26] üìÅ Directory already exists: all resumes/default
[2025-07-12 01:51:26] üìÅ Directory already exists: all resumes/temp
[2025-07-12 01:51:26] IF YOU HAVE MORE THAN 10 TABS OPENED, PLEASE CLOSE OR BOOKMARK THEM!
[2025-07-12 01:51:26] SAFE MODE: Using guest profile, no history saved!
[2025-07-12 01:51:30] Critical error in main:
[2025-07-12 01:51:30] [ERROR] The variable "current_experience" in "config/search.py" must be an Integer!
Received "5" of type "<class 'str'>" instead!

Solution:
Please open "config/search.py" and update "current_experience" to be an Integer.
Example: `current_experience = 10`

NOTE: Do NOT surround Integer values in quotes ("10")X !

: In main
Traceback (most recent call last):
  File "/home/wagle/garbageGold/app/linkedinBot/linkedinRun.py", line 802, in linkedinMain
    validate_config()
    ~~~~~~~~~~~~~~~^^
  File "/home/wagle/garbageGold/app/linkedinBot/utils/validator.py", line 202, in validate_config
    validate_search()
    ~~~~~~~~~~~~~~~^^
  File "/home/wagle/garbageGold/app/linkedinBot/utils/validator.py", line 128, in validate_search
    check_int(current_experience, "current_experience", -1)
    ~~~~~~~~~^^^^^^^^^^^^^^^^^^^^^^^^^^^^^^^^^^^^^^^^^^^^^^
  File "/home/wagle/garbageGold/app/linkedinBot/utils/validator.py", line 5, in check_int
    if not isinstance(var, int): raise TypeError(f'The variable "{var_name}" in "{__validation_file_path}" must be an Integer!\nReceived "{var}" of type "{type(var)}" instead!\n\nSolution:\nPlease open "{__validation_file_path}" and update "{var_name}" to be an Integer.\nExample: `{var_name} = 10`\n\nNOTE: Do NOT surround Integer values in quotes ("10")X !\n\n')
                                 ^^^^^^^^^^^^^^^^^^^^^^^^^^^^^^^^^^^^^^^^^^^^^^^^^^^^^^^^^^^^^^^^^^^^^^^^^^^^^^^^^^^^^^^^^^^^^^^^^^^^^^^^^^^^^^^^^^^^^^^^^^^^^^^^^^^^^^^^^^^^^^^^^^^^^^^^^^^^^^^^^^^^^^^^^^^^^^^^^^^^^^^^^^^^^^^^^^^^^^^^^^^^^^^^^^^^^^^^^^^^^^^^^^^^^^^^^^^^^^^^^^^^^^^^^^^^^^^^^^^^^^^^^^^^^^^^^^^^^^^^^^^^^^^^^^^^^^^^^^^^^^^^^^^^^^^^^^^^^^^^^^^^^^^^^^^
TypeError: The variable "current_experience" in "config/search.py" must be an Integer!
Received "5" of type "<class 'str'>" instead!

Solution:
Please open "config/search.py" and update "current_experience" to be an Integer.
Example: `current_experience = 10`

NOTE: Do NOT surround Integer values in quotes ("10")X !



[2025-07-12 02:03:34] 
============================================================
[2025-07-12 02:03:34] FINAL STATISTICS
[2025-07-12 02:03:34] ============================================================
[2025-07-12 02:03:34] Total runs:                     1
[2025-07-12 02:03:34] Jobs Easy Applied:              0
[2025-07-12 02:03:34] External job links collected:   0
[2025-07-12 02:03:34]                               ----------
[2025-07-12 02:03:34] Total applied or collected:     0
[2025-07-12 02:03:34] 
Failed jobs:                    0
[2025-07-12 02:03:34] Irrelevant jobs skipped:        0
[2025-07-12 02:03:34] 
The road to success and the road to failure are almost exactly the same. The difference is perseverance.

Best regards,
Sai Vignesh Golla
https://www.linkedin.com/in/saivigneshgolla/
[2025-07-12 02:09:13] üìÅ Directory already exists: all excels
[2025-07-12 02:09:13] üìÅ Directory already exists: all excels
[2025-07-12 02:09:13] üìÅ Directory already exists: logs/screenshots
[2025-07-12 02:09:13] üìÅ Directory already exists: all resumes/default
[2025-07-12 02:09:13] üìÅ Directory already exists: all resumes/temp
[2025-07-12 02:09:13] IF YOU HAVE MORE THAN 10 TABS OPENED, PLEASE CLOSE OR BOOKMARK THEM!
[2025-07-12 02:09:13] SAFE MODE: Using guest profile, no history saved!
[2025-07-12 02:09:19] Critical error in main:
[2025-07-12 02:09:19] [ERROR] The variable "current_experience" in "config/search.py" must be an Integer!
Received "5" of type "<class 'str'>" instead!

Solution:
Please open "config/search.py" and update "current_experience" to be an Integer.
Example: `current_experience = 10`

NOTE: Do NOT surround Integer values in quotes ("10")X !

: In main
Traceback (most recent call last):
  File "/home/wagle/garbageGold/app/linkedinBot/linkedinRun.py", line 805, in linkedinMain
    validate_config()
    ~~~~~~~~~~~~~~~^^
  File "/home/wagle/garbageGold/app/linkedinBot/utils/validator.py", line 202, in validate_config
    validate_search()
    ~~~~~~~~~~~~~~~^^
  File "/home/wagle/garbageGold/app/linkedinBot/utils/validator.py", line 128, in validate_search
    check_int(current_experience, "current_experience", -1)
    ~~~~~~~~~^^^^^^^^^^^^^^^^^^^^^^^^^^^^^^^^^^^^^^^^^^^^^^
  File "/home/wagle/garbageGold/app/linkedinBot/utils/validator.py", line 5, in check_int
    if not isinstance(var, int): raise TypeError(f'The variable "{var_name}" in "{__validation_file_path}" must be an Integer!\nReceived "{var}" of type "{type(var)}" instead!\n\nSolution:\nPlease open "{__validation_file_path}" and update "{var_name}" to be an Integer.\nExample: `{var_name} = 10`\n\nNOTE: Do NOT surround Integer values in quotes ("10")X !\n\n')
                                 ^^^^^^^^^^^^^^^^^^^^^^^^^^^^^^^^^^^^^^^^^^^^^^^^^^^^^^^^^^^^^^^^^^^^^^^^^^^^^^^^^^^^^^^^^^^^^^^^^^^^^^^^^^^^^^^^^^^^^^^^^^^^^^^^^^^^^^^^^^^^^^^^^^^^^^^^^^^^^^^^^^^^^^^^^^^^^^^^^^^^^^^^^^^^^^^^^^^^^^^^^^^^^^^^^^^^^^^^^^^^^^^^^^^^^^^^^^^^^^^^^^^^^^^^^^^^^^^^^^^^^^^^^^^^^^^^^^^^^^^^^^^^^^^^^^^^^^^^^^^^^^^^^^^^^^^^^^^^^^^^^^^^^^^^^^^
TypeError: The variable "current_experience" in "config/search.py" must be an Integer!
Received "5" of type "<class 'str'>" instead!

Solution:
Please open "config/search.py" and update "current_experience" to be an Integer.
Example: `current_experience = 10`

NOTE: Do NOT surround Integer values in quotes ("10")X !



[2025-07-12 02:09:27] 
============================================================
[2025-07-12 02:09:27] FINAL STATISTICS
[2025-07-12 02:09:27] ============================================================
[2025-07-12 02:09:27] Total runs:                     1
[2025-07-12 02:09:27] Jobs Easy Applied:              0
[2025-07-12 02:09:27] External job links collected:   0
[2025-07-12 02:09:27]                               ----------
[2025-07-12 02:09:27] Total applied or collected:     0
[2025-07-12 02:09:27] 
Failed jobs:                    0
[2025-07-12 02:09:27] Irrelevant jobs skipped:        0
[2025-07-12 02:09:27] 
Success is walking from failure to failure with no loss of enthusiasm. - Winston Churchill

Best regards : )
[2025-07-12 02:26:40] üìÅ Directory already exists: all excels
[2025-07-12 02:26:40] üìÅ Directory already exists: all excels
[2025-07-12 02:26:40] üìÅ Directory already exists: logs/screenshots
[2025-07-12 02:26:40] üìÅ Directory already exists: all resumes/default
[2025-07-12 02:26:40] üìÅ Directory already exists: all resumes/temp
[2025-07-12 02:26:40] IF YOU HAVE MORE THAN 10 TABS OPENED, PLEASE CLOSE OR BOOKMARK THEM!
[2025-07-12 02:26:40] SAFE MODE: Using guest profile, no history saved!
[2025-07-12 02:30:32] üìÅ Directory already exists: all excels
[2025-07-12 02:30:32] üìÅ Directory already exists: all excels
[2025-07-12 02:30:32] üìÅ Directory already exists: logs/screenshots
[2025-07-12 02:30:32] üìÅ Directory already exists: all resumes/default
[2025-07-12 02:30:32] üìÅ Directory already exists: all resumes/temp
[2025-07-12 02:30:32] IF YOU HAVE MORE THAN 10 TABS OPENED, PLEASE CLOSE OR BOOKMARK THEM!
[2025-07-12 02:30:32] SAFE MODE: Using guest profile, no history saved!
[2025-07-12 02:30:36] Critical error in main:
[2025-07-12 02:30:36] [ERROR] Invalid input for us_citizenship. Expecting a value from ['U.S. Citizen/Permanent Resident', 'Non-citizen allowed to work for any employer', 'Non-citizen allowed to work for current employer', 'Non-citizen seeking work authorization', 'Canadian Citizen/Permanent Resident', 'Other'], not Yes!: In main
Traceback (most recent call last):
  File "/home/wagle/garbageGold/app/linkedinBot/linkedinRun.py", line 805, in linkedinMain
    validate_config()
    ~~~~~~~~~~~~~~~^^
  File "/home/wagle/garbageGold/app/linkedinBot/utils/validator.py", line 201, in validate_config
    validate_questions()
    ~~~~~~~~~~~~~~~~~~^^
  File "/home/wagle/garbageGold/app/linkedinBot/utils/validator.py", line 72, in validate_questions
    check_string(us_citizenship, "us_citizenship", ["U.S. Citizen/Permanent Resident", "Non-citizen allowed to work for any employer", "Non-citizen allowed to work for current employer", "Non-citizen seeking work authorization", "Canadian Citizen/Permanent Resident", "Other"])
    ~~~~~~~~~~~~^^^^^^^^^^^^^^^^^^^^^^^^^^^^^^^^^^^^^^^^^^^^^^^^^^^^^^^^^^^^^^^^^^^^^^^^^^^^^^^^^^^^^^^^^^^^^^^^^^^^^^^^^^^^^^^^^^^^^^^^^^^^^^^^^^^^^^^^^^^^^^^^^^^^^^^^^^^^^^^^^^^^^^^^^^^^^^^^^^^^^^^^^^^^^^^^^^^^^^^^^^^^^^^^^^^^^^^^^^^^^^^^^^^^^^^^^^^^^^^^^^^^^^^^^^^^^^^^^^^^^
  File "/home/wagle/garbageGold/app/linkedinBot/utils/validator.py", line 16, in check_string
    if len(options) > 0 and var not in options: raise ValueError(f'Invalid input for {var_name}. Expecting a value from {options}, not {var}!')
                                                ^^^^^^^^^^^^^^^^^^^^^^^^^^^^^^^^^^^^^^^^^^^^^^^^^^^^^^^^^^^^^^^^^^^^^^^^^^^^^^^^^^^^^^^^^^^^^^^
ValueError: Invalid input for us_citizenship. Expecting a value from ['U.S. Citizen/Permanent Resident', 'Non-citizen allowed to work for any employer', 'Non-citizen allowed to work for current employer', 'Non-citizen seeking work authorization', 'Canadian Citizen/Permanent Resident', 'Other'], not Yes!

[2025-07-12 02:32:01] üìÅ Directory already exists: all excels
[2025-07-12 02:32:01] üìÅ Directory already exists: all excels
[2025-07-12 02:32:01] üìÅ Directory already exists: logs/screenshots
[2025-07-12 02:32:01] üìÅ Directory already exists: all resumes/default
[2025-07-12 02:32:01] üìÅ Directory already exists: all resumes/temp
[2025-07-12 02:32:01] IF YOU HAVE MORE THAN 10 TABS OPENED, PLEASE CLOSE OR BOOKMARK THEM!
[2025-07-12 02:32:01] SAFE MODE: Using guest profile, no history saved!
[2025-07-12 02:32:05] Critical error in main:
[2025-07-12 02:32:05] [ERROR] Invalid input for username. Expecting a String of length at least 5!: In main
Traceback (most recent call last):
  File "/home/wagle/garbageGold/app/linkedinBot/linkedinRun.py", line 805, in linkedinMain
    validate_config()
    ~~~~~~~~~~~~~~~^^
  File "/home/wagle/garbageGold/app/linkedinBot/utils/validator.py", line 203, in validate_config
    validate_secrets()
    ~~~~~~~~~~~~~~~~^^
  File "/home/wagle/garbageGold/app/linkedinBot/utils/validator.py", line 141, in validate_secrets
    check_string(username, "username", min_length=5)
    ~~~~~~~~~~~~^^^^^^^^^^^^^^^^^^^^^^^^^^^^^^^^^^^^
  File "/home/wagle/garbageGold/app/linkedinBot/utils/validator.py", line 15, in check_string
    if min_length > 0 and len(var) < min_length: raise ValueError(f'Invalid input for {var_name}. Expecting a String of length at least {min_length}!')
                                                 ^^^^^^^^^^^^^^^^^^^^^^^^^^^^^^^^^^^^^^^^^^^^^^^^^^^^^^^^^^^^^^^^^^^^^^^^^^^^^^^^^^^^^^^^^^^^^^^^^^^^^^
ValueError: Invalid input for username. Expecting a String of length at least 5!

[2025-07-12 02:32:17] 
============================================================
[2025-07-12 02:32:17] FINAL STATISTICS
[2025-07-12 02:32:17] ============================================================
[2025-07-12 02:32:17] Total runs:                     1
[2025-07-12 02:32:17] Jobs Easy Applied:              0
[2025-07-12 02:32:17] External job links collected:   0
[2025-07-12 02:32:17]                               ----------
[2025-07-12 02:32:17] Total applied or collected:     0
[2025-07-12 02:32:17] 
Failed jobs:                    0
[2025-07-12 02:32:17] Irrelevant jobs skipped:        0
[2025-07-12 02:32:17] 
The way to get started is to quit talking and begin doing. - Walt Disney

Best regards : )
[2025-07-12 02:32:29] 
============================================================
[2025-07-12 02:32:29] FINAL STATISTICS
[2025-07-12 02:32:29] ============================================================
[2025-07-12 02:32:29] Total runs:                     1
[2025-07-12 02:32:29] Jobs Easy Applied:              0
[2025-07-12 02:32:29] External job links collected:   0
[2025-07-12 02:32:29]                               ----------
[2025-07-12 02:32:29] Total applied or collected:     0
[2025-07-12 02:32:29] 
Failed jobs:                    0
[2025-07-12 02:32:29] Irrelevant jobs skipped:        0
[2025-07-12 02:32:29] 
Success is walking from failure to failure with no loss of enthusiasm. - Winston Churchill

Best regards : )
[2025-07-12 02:41:49] üìÅ Directory already exists: all excels
[2025-07-12 02:41:49] üìÅ Directory already exists: all excels
[2025-07-12 02:41:49] üìÅ Directory already exists: logs/screenshots
[2025-07-12 02:41:49] üìÅ Directory already exists: all resumes/default
[2025-07-12 02:41:49] üìÅ Directory already exists: all resumes/temp
[2025-07-12 02:41:49] IF YOU HAVE MORE THAN 10 TABS OPENED, PLEASE CLOSE OR BOOKMARK THEM!
[2025-07-12 02:41:49] SAFE MODE: Using guest profile, no history saved!
[2025-07-12 02:41:52] Critical error in main:
[2025-07-12 02:41:52] [ERROR] Invalid input for llm_api_url. Expecting a String of length at least 5!: In main
Traceback (most recent call last):
  File "/home/wagle/garbageGold/app/linkedinBot/linkedinRun.py", line 805, in linkedinMain
    validate_config()
    ~~~~~~~~~~~~~~~^^
  File "/home/wagle/garbageGold/app/linkedinBot/utils/validator.py", line 203, in validate_config
    validate_secrets()
    ~~~~~~~~~~~~~~~~^^
  File "/home/wagle/garbageGold/app/linkedinBot/utils/validator.py", line 145, in validate_secrets
    check_string(llm_api_url, "llm_api_url", min_length=5)
    ~~~~~~~~~~~~^^^^^^^^^^^^^^^^^^^^^^^^^^^^^^^^^^^^^^^^^^
  File "/home/wagle/garbageGold/app/linkedinBot/utils/validator.py", line 15, in check_string
    if min_length > 0 and len(var) < min_length: raise ValueError(f'Invalid input for {var_name}. Expecting a String of length at least {min_length}!')
                                                 ^^^^^^^^^^^^^^^^^^^^^^^^^^^^^^^^^^^^^^^^^^^^^^^^^^^^^^^^^^^^^^^^^^^^^^^^^^^^^^^^^^^^^^^^^^^^^^^^^^^^^^
ValueError: Invalid input for llm_api_url. Expecting a String of length at least 5!

[2025-07-12 03:42:00] üìÅ Directory already exists: all excels
[2025-07-12 03:42:00] üìÅ Directory already exists: all excels
[2025-07-12 03:42:00] üìÅ Directory already exists: logs/screenshots
[2025-07-12 03:42:00] üìÅ Directory already exists: all resumes/default
[2025-07-12 03:42:00] üìÅ Directory already exists: all resumes/temp
[2025-07-12 03:42:00] IF YOU HAVE MORE THAN 10 TABS OPENED, PLEASE CLOSE OR BOOKMARK THEM!
[2025-07-12 03:42:00] SAFE MODE: Using guest profile, no history saved!
[2025-07-12 03:42:12] Critical error in main:
[2025-07-12 03:42:12] [ERROR] Invalid input for ai_provider. Expecting a value from ['openai', 'deepseek'], not DeepSeek!: In main
Traceback (most recent call last):
  File "/home/wagle/garbageGold/app/linkedinBot/linkedinRun.py", line 805, in linkedinMain
    validate_config()
    ~~~~~~~~~~~~~~~^^
  File "/home/wagle/garbageGold/app/linkedinBot/utils/validator.py", line 203, in validate_config
    validate_secrets()
    ~~~~~~~~~~~~~~~~^^
  File "/home/wagle/garbageGold/app/linkedinBot/utils/validator.py", line 153, in validate_secrets
    check_string(ai_provider, "ai_provider", ["openai", "deepseek"])
    ~~~~~~~~~~~~^^^^^^^^^^^^^^^^^^^^^^^^^^^^^^^^^^^^^^^^^^^^^^^^^^^^
  File "/home/wagle/garbageGold/app/linkedinBot/utils/validator.py", line 16, in check_string
    if len(options) > 0 and var not in options: raise ValueError(f'Invalid input for {var_name}. Expecting a value from {options}, not {var}!')
                                                ^^^^^^^^^^^^^^^^^^^^^^^^^^^^^^^^^^^^^^^^^^^^^^^^^^^^^^^^^^^^^^^^^^^^^^^^^^^^^^^^^^^^^^^^^^^^^^^
ValueError: Invalid input for ai_provider. Expecting a value from ['openai', 'deepseek'], not DeepSeek!

[2025-07-12 03:42:22] 
============================================================
[2025-07-12 03:42:22] FINAL STATISTICS
[2025-07-12 03:42:22] ============================================================
[2025-07-12 03:42:22] Total runs:                     1
[2025-07-12 03:42:22] Jobs Easy Applied:              0
[2025-07-12 03:42:22] External job links collected:   0
[2025-07-12 03:42:22]                               ----------
[2025-07-12 03:42:22] Total applied or collected:     0
[2025-07-12 03:42:22] 
Failed jobs:                    0
[2025-07-12 03:42:22] Irrelevant jobs skipped:        0
[2025-07-12 03:42:22] 
I have not failed. I've just found 10,000 ways that won't work. - Thomas Edison

Best regards : )
[2025-07-12 03:42:40] 
============================================================
[2025-07-12 03:42:40] FINAL STATISTICS
[2025-07-12 03:42:40] ============================================================
[2025-07-12 03:42:40] Total runs:                     1
[2025-07-12 03:42:40] Jobs Easy Applied:              0
[2025-07-12 03:42:40] External job links collected:   0
[2025-07-12 03:42:40]                               ----------
[2025-07-12 03:42:40] Total applied or collected:     0
[2025-07-12 03:42:40] 
Failed jobs:                    0
[2025-07-12 03:42:40] Irrelevant jobs skipped:        0
[2025-07-12 03:42:40] 
Don't be afraid to give up the good to go for the great. - John D. Rockefeller

Best regards : )
[2025-07-12 03:43:44] üìÅ Directory already exists: all excels
[2025-07-12 03:43:44] üìÅ Directory already exists: all excels
[2025-07-12 03:43:44] üìÅ Directory already exists: logs/screenshots
[2025-07-12 03:43:44] üìÅ Directory already exists: all resumes/default
[2025-07-12 03:43:44] üìÅ Directory already exists: all resumes/temp
[2025-07-12 03:43:44] IF YOU HAVE MORE THAN 10 TABS OPENED, PLEASE CLOSE OR BOOKMARK THEM!
[2025-07-12 03:43:44] SAFE MODE: Using guest profile, no history saved!
[2025-07-12 03:43:48] üìÅ Directory already exists: all excels
[2025-07-12 03:43:48] üìÅ Directory already exists: all excels
[2025-07-12 03:43:48] üìÅ Directory already exists: logs/screenshots
[2025-07-12 03:43:48] üìÅ Directory already exists: all resumes/default
[2025-07-12 03:43:48] üìÅ Directory already exists: all resumes/temp
[2025-07-12 03:43:48] IF YOU HAVE MORE THAN 10 TABS OPENED, PLEASE CLOSE OR BOOKMARK THEM!
[2025-07-12 03:43:48] SAFE MODE: Using guest profile, no history saved!
[2025-07-12 03:44:48] [ERROR] Unknown: Could not find link with text: 'Sign in'
Traceback (most recent call last):
  File "/home/wagle/garbageGold/app/linkedinBot/browser/clickers_and_finders.py", line 264, in try_linkText
    element = driver.find_element(By.LINK_TEXT, linkText)
  File "/home/wagle/garbageGold/.venv/lib/python3.13/site-packages/selenium/webdriver/remote/webdriver.py", line 748, in find_element
    return self.execute(Command.FIND_ELEMENT, {"using": by, "value": value})["value"]
           ~~~~~~~~~~~~^^^^^^^^^^^^^^^^^^^^^^^^^^^^^^^^^^^^^^^^^^^^^^^^^^^^^
  File "/home/wagle/garbageGold/.venv/lib/python3.13/site-packages/selenium/webdriver/remote/webdriver.py", line 354, in execute
    self.error_handler.check_response(response)
    ~~~~~~~~~~~~~~~~~~~~~~~~~~~~~~~~~^^^^^^^^^^
  File "/home/wagle/garbageGold/.venv/lib/python3.13/site-packages/selenium/webdriver/remote/errorhandler.py", line 229, in check_response
    raise exception_class(message, screen, stacktrace)
selenium.common.exceptions.NoSuchElementException: Message: no such element: Unable to locate element: {"method":"link text","selector":"Sign in"}
  (Session info: chrome=138.0.7204.49); For documentation on this error, please visit: https://www.selenium.dev/documentation/webdriver/troubleshooting/errors#no-such-element-exception
Stacktrace:
#0 0x5b9114fd623a <unknown>
#1 0x5b9114a80ab0 <unknown>
#2 0x5b9114ad26f0 <unknown>
#3 0x5b9114ad28e1 <unknown>
#4 0x5b9114b20b94 <unknown>
#5 0x5b9114af81cd <unknown>
#6 0x5b9114b1dfee <unknown>
#7 0x5b9114af7f73 <unknown>
#8 0x5b9114ac4aeb <unknown>
#9 0x5b9114ac5751 <unknown>
#10 0x5b9114f9ab4b <unknown>
#11 0x5b9114f9e929 <unknown>
#12 0x5b9114f81929 <unknown>
#13 0x5b9114f9f4e8 <unknown>
#14 0x5b9114f660df <unknown>
#15 0x5b9114fc38e8 <unknown>
#16 0x5b9114fc3ac6 <unknown>
#17 0x5b9114fd5556 <unknown>
#18 0x74b47d294ac3 <unknown>


[2025-07-12 03:44:48] [ERROR] Unknown: Could not find element with xpath: '//button[@type="submit" and contains(text(), "Sign in")]'
Traceback (most recent call last):
  File "/home/wagle/garbageGold/app/linkedinBot/browser/clickers_and_finders.py", line 236, in try_xp
    element = driver.find_element(By.XPATH, xpath)
  File "/home/wagle/garbageGold/.venv/lib/python3.13/site-packages/selenium/webdriver/remote/webdriver.py", line 748, in find_element
    return self.execute(Command.FIND_ELEMENT, {"using": by, "value": value})["value"]
           ~~~~~~~~~~~~^^^^^^^^^^^^^^^^^^^^^^^^^^^^^^^^^^^^^^^^^^^^^^^^^^^^^
  File "/home/wagle/garbageGold/.venv/lib/python3.13/site-packages/selenium/webdriver/remote/webdriver.py", line 354, in execute
    self.error_handler.check_response(response)
    ~~~~~~~~~~~~~~~~~~~~~~~~~~~~~~~~~^^^^^^^^^^
  File "/home/wagle/garbageGold/.venv/lib/python3.13/site-packages/selenium/webdriver/remote/errorhandler.py", line 229, in check_response
    raise exception_class(message, screen, stacktrace)
selenium.common.exceptions.NoSuchElementException: Message: no such element: Unable to locate element: {"method":"xpath","selector":"//button[@type="submit" and contains(text(), "Sign in")]"}
  (Session info: chrome=138.0.7204.49); For documentation on this error, please visit: https://www.selenium.dev/documentation/webdriver/troubleshooting/errors#no-such-element-exception
Stacktrace:
#0 0x5b9114fd623a <unknown>
#1 0x5b9114a80ab0 <unknown>
#2 0x5b9114ad26f0 <unknown>
#3 0x5b9114ad28e1 <unknown>
#4 0x5b9114b20b94 <unknown>
#5 0x5b9114af81cd <unknown>
#6 0x5b9114b1dfee <unknown>
#7 0x5b9114af7f73 <unknown>
#8 0x5b9114ac4aeb <unknown>
#9 0x5b9114ac5751 <unknown>
#10 0x5b9114f9ab4b <unknown>
#11 0x5b9114f9e929 <unknown>
#12 0x5b9114f81929 <unknown>
#13 0x5b9114f9f4e8 <unknown>
#14 0x5b9114f660df <unknown>
#15 0x5b9114fc38e8 <unknown>
#16 0x5b9114fc3ac6 <unknown>
#17 0x5b9114fd5556 <unknown>
#18 0x74b47d294ac3 <unknown>


[2025-07-12 03:44:48] [ERROR] Unknown: Could not find link with text: 'Join now'
Traceback (most recent call last):
  File "/home/wagle/garbageGold/app/linkedinBot/browser/clickers_and_finders.py", line 264, in try_linkText
    element = driver.find_element(By.LINK_TEXT, linkText)
  File "/home/wagle/garbageGold/.venv/lib/python3.13/site-packages/selenium/webdriver/remote/webdriver.py", line 748, in find_element
    return self.execute(Command.FIND_ELEMENT, {"using": by, "value": value})["value"]
           ~~~~~~~~~~~~^^^^^^^^^^^^^^^^^^^^^^^^^^^^^^^^^^^^^^^^^^^^^^^^^^^^^
  File "/home/wagle/garbageGold/.venv/lib/python3.13/site-packages/selenium/webdriver/remote/webdriver.py", line 354, in execute
    self.error_handler.check_response(response)
    ~~~~~~~~~~~~~~~~~~~~~~~~~~~~~~~~~^^^^^^^^^^
  File "/home/wagle/garbageGold/.venv/lib/python3.13/site-packages/selenium/webdriver/remote/errorhandler.py", line 229, in check_response
    raise exception_class(message, screen, stacktrace)
selenium.common.exceptions.NoSuchElementException: Message: no such element: Unable to locate element: {"method":"link text","selector":"Join now"}
  (Session info: chrome=138.0.7204.49); For documentation on this error, please visit: https://www.selenium.dev/documentation/webdriver/troubleshooting/errors#no-such-element-exception
Stacktrace:
#0 0x5b9114fd623a <unknown>
#1 0x5b9114a80ab0 <unknown>
#2 0x5b9114ad26f0 <unknown>
#3 0x5b9114ad28e1 <unknown>
#4 0x5b9114b20b94 <unknown>
#5 0x5b9114af81cd <unknown>
#6 0x5b9114b1dfee <unknown>
#7 0x5b9114af7f73 <unknown>
#8 0x5b9114ac4aeb <unknown>
#9 0x5b9114ac5751 <unknown>
#10 0x5b9114f9ab4b <unknown>
#11 0x5b9114f9e929 <unknown>
#12 0x5b9114f81929 <unknown>
#13 0x5b9114f9f4e8 <unknown>
#14 0x5b9114f660df <unknown>
#15 0x5b9114fc38e8 <unknown>
#16 0x5b9114fc3ac6 <unknown>
#17 0x5b9114fd5556 <unknown>
#18 0x74b47d294ac3 <unknown>


[2025-07-12 03:44:48] Didn't find Sign in link, so assuming user is logged in!
[2025-07-12 03:44:48] Initializing AI client for deepseek...
[2025-07-12 03:44:48] Creating DeepSeek client...
[2025-07-12 03:44:49] ‚úÖ DeepSeek client created
[2025-07-12 03:44:49] üîó API URL: https://api.deepseek.com
[2025-07-12 03:44:49] üß† Model: deepseek-chat
[2025-07-12 04:05:34] üìÅ Directory already exists: all excels
[2025-07-12 04:05:34] üìÅ Directory already exists: all excels
[2025-07-12 04:05:34] üìÅ Directory already exists: logs/screenshots
[2025-07-12 04:05:34] üìÅ Directory already exists: all resumes/default
[2025-07-12 04:05:34] üìÅ Directory already exists: all resumes/temp
[2025-07-12 04:05:34] IF YOU HAVE MORE THAN 10 TABS OPENED, PLEASE CLOSE OR BOOKMARK THEM!
[2025-07-12 04:05:34] SAFE MODE: Using guest profile, no history saved!
[2025-07-12 04:05:38] üìÅ Directory already exists: all excels
[2025-07-12 04:05:38] üìÅ Directory already exists: all excels
[2025-07-12 04:05:38] üìÅ Directory already exists: logs/screenshots
[2025-07-12 04:05:38] üìÅ Directory already exists: all resumes/default
[2025-07-12 04:05:38] üìÅ Directory already exists: all resumes/temp
[2025-07-12 04:05:38] IF YOU HAVE MORE THAN 10 TABS OPENED, PLEASE CLOSE OR BOOKMARK THEM!
[2025-07-12 04:05:38] SAFE MODE: Using guest profile, no history saved!
[2025-07-12 04:05:46] The CSV file 'all excels/all_applied_applications_history.csv' does not exist.
[2025-07-12 04:05:46] Starting continuous run with 10 search terms
[2025-07-12 04:05:46] 
====================================================================================================
[2025-07-12 04:05:46] Cycle 1 - 2025-07-12 04:05:46.815949
[2025-07-12 04:05:46] Looking for jobs posted within 'Past week' sorted by 'Most recent'
[2025-07-12 04:05:46] Error in continuous run:
[2025-07-12 04:05:46] [ERROR] Message: invalid session id: session deleted as the browser has closed the connection
from disconnected: not connected to DevTools
  (Session info: chrome=138.0.7204.49)
Stacktrace:
#0 0x57b6b4d3823a <unknown>
#1 0x57b6b47e2ab0 <unknown>
#2 0x57b6b47c96fe <unknown>
#3 0x57b6b47f1669 <unknown>
#4 0x57b6b486268f <unknown>
#5 0x57b6b487f992 <unknown>
#6 0x57b6b4859f73 <unknown>
#7 0x57b6b4826aeb <unknown>
#8 0x57b6b4827751 <unknown>
#9 0x57b6b4cfcb4b <unknown>
#10 0x57b6b4d00929 <unknown>
#11 0x57b6b4ce3929 <unknown>
#12 0x57b6b4d014e8 <unknown>
#13 0x57b6b4cc80df <unknown>
#14 0x57b6b4d258e8 <unknown>
#15 0x57b6b4d25ac6 <unknown>
#16 0x57b6b4d37556 <unknown>
#17 0x793611094ac3 <unknown>
: In run_continuous
Traceback (most recent call last):
  File "/home/wagle/garbageGold/app/linkedinBot/linkedinRun.py", line 690, in run_continuous
    processed = self.run_application_cycle(search_terms)
  File "/home/wagle/garbageGold/app/linkedinBot/linkedinRun.py", line 670, in run_application_cycle
    processed = self.process_search_term(search_term)
  File "/home/wagle/garbageGold/app/linkedinBot/linkedinRun.py", line 562, in process_search_term
    self.driver.get(f"https://www.linkedin.com/jobs/search/?keywords={search_term}")
    ~~~~~~~~~~~~~~~^^^^^^^^^^^^^^^^^^^^^^^^^^^^^^^^^^^^^^^^^^^^^^^^^^^^^^^^^^^^^^^^^
  File "/home/wagle/garbageGold/.venv/lib/python3.13/site-packages/selenium/webdriver/remote/webdriver.py", line 363, in get
    self.execute(Command.GET, {"url": url})
    ~~~~~~~~~~~~^^^^^^^^^^^^^^^^^^^^^^^^^^^
  File "/home/wagle/garbageGold/.venv/lib/python3.13/site-packages/selenium/webdriver/remote/webdriver.py", line 354, in execute
    self.error_handler.check_response(response)
    ~~~~~~~~~~~~~~~~~~~~~~~~~~~~~~~~~^^^^^^^^^^
  File "/home/wagle/garbageGold/.venv/lib/python3.13/site-packages/selenium/webdriver/remote/errorhandler.py", line 229, in check_response
    raise exception_class(message, screen, stacktrace)
selenium.common.exceptions.InvalidSessionIdException: Message: invalid session id: session deleted as the browser has closed the connection
from disconnected: not connected to DevTools
  (Session info: chrome=138.0.7204.49)
Stacktrace:
#0 0x57b6b4d3823a <unknown>
#1 0x57b6b47e2ab0 <unknown>
#2 0x57b6b47c96fe <unknown>
#3 0x57b6b47f1669 <unknown>
#4 0x57b6b486268f <unknown>
#5 0x57b6b487f992 <unknown>
#6 0x57b6b4859f73 <unknown>
#7 0x57b6b4826aeb <unknown>
#8 0x57b6b4827751 <unknown>
#9 0x57b6b4cfcb4b <unknown>
#10 0x57b6b4d00929 <unknown>
#11 0x57b6b4ce3929 <unknown>
#12 0x57b6b4d014e8 <unknown>
#13 0x57b6b4cc80df <unknown>
#14 0x57b6b4d258e8 <unknown>
#15 0x57b6b4d25ac6 <unknown>
#16 0x57b6b4d37556 <unknown>
#17 0x793611094ac3 <unknown>


[2025-07-12 04:05:46] 
============================================================
[2025-07-12 04:05:46] FINAL STATISTICS
[2025-07-12 04:05:46] ============================================================
[2025-07-12 04:05:46] Total runs:                     1
[2025-07-12 04:05:46] Jobs Easy Applied:              0
[2025-07-12 04:05:46] External job links collected:   0
[2025-07-12 04:05:46]                               ----------
[2025-07-12 04:05:46] Total applied or collected:     0
[2025-07-12 04:05:46] 
Failed jobs:                    0
[2025-07-12 04:05:46] Irrelevant jobs skipped:        0
[2025-07-12 04:05:46] 
Success is walking from failure to failure with no loss of enthusiasm. - Winston Churchill

Best regards : )
[2025-07-12 04:05:49] Closing OpenAI client...
[2025-07-12 04:05:49] OpenAI client closed successfully
[2025-07-12 04:05:49] Closed deepseek AI client.
[2025-07-12 04:05:49] Browser closed successfully
[2025-07-12 04:06:07] Critical error in main:
[2025-07-12 04:06:07] [ERROR] Message: invalid session id: session deleted as the browser has closed the connection
from disconnected: not connected to DevTools
  (Session info: chrome=138.0.7204.49)
Stacktrace:
#0 0x55f7a3aac23a <unknown>
#1 0x55f7a3556ab0 <unknown>
#2 0x55f7a353d6fe <unknown>
#3 0x55f7a3565669 <unknown>
#4 0x55f7a35d668f <unknown>
#5 0x55f7a35f3992 <unknown>
#6 0x55f7a35cdf73 <unknown>
#7 0x55f7a359aaeb <unknown>
#8 0x55f7a359b751 <unknown>
#9 0x55f7a3a70b4b <unknown>
#10 0x55f7a3a74929 <unknown>
#11 0x55f7a3a57929 <unknown>
#12 0x55f7a3a754e8 <unknown>
#13 0x55f7a3a3c0df <unknown>
#14 0x55f7a3a998e8 <unknown>
#15 0x55f7a3a99ac6 <unknown>
#16 0x55f7a3aab556 <unknown>
#17 0x73d5b5494ac3 <unknown>
: In main
Traceback (most recent call last):
  File "/home/wagle/garbageGold/app/linkedinBot/linkedinRun.py", line 806, in linkedinMain
    applier.initialize_browser()
    ~~~~~~~~~~~~~~~~~~~~~~~~~~^^
  File "/home/wagle/garbageGold/app/linkedinBot/linkedinRun.py", line 299, in initialize_browser
    if not is_logged_in_LN():
           ~~~~~~~~~~~~~~~^^
  File "/home/wagle/garbageGold/app/linkedinBot/auth/session.py", line 10, in is_logged_in_LN
    if driver.current_url == "https://www.linkedin.com/feed/": return True
       ^^^^^^^^^^^^^^^^^^
  File "/home/wagle/garbageGold/.venv/lib/python3.13/site-packages/selenium/webdriver/remote/webdriver.py", line 444, in current_url
    return self.execute(Command.GET_CURRENT_URL)["value"]
           ~~~~~~~~~~~~^^^^^^^^^^^^^^^^^^^^^^^^^
  File "/home/wagle/garbageGold/.venv/lib/python3.13/site-packages/selenium/webdriver/remote/webdriver.py", line 354, in execute
    self.error_handler.check_response(response)
    ~~~~~~~~~~~~~~~~~~~~~~~~~~~~~~~~~^^^^^^^^^^
  File "/home/wagle/garbageGold/.venv/lib/python3.13/site-packages/selenium/webdriver/remote/errorhandler.py", line 229, in check_response
    raise exception_class(message, screen, stacktrace)
selenium.common.exceptions.InvalidSessionIdException: Message: invalid session id: session deleted as the browser has closed the connection
from disconnected: not connected to DevTools
  (Session info: chrome=138.0.7204.49)
Stacktrace:
#0 0x55f7a3aac23a <unknown>
#1 0x55f7a3556ab0 <unknown>
#2 0x55f7a353d6fe <unknown>
#3 0x55f7a3565669 <unknown>
#4 0x55f7a35d668f <unknown>
#5 0x55f7a35f3992 <unknown>
#6 0x55f7a35cdf73 <unknown>
#7 0x55f7a359aaeb <unknown>
#8 0x55f7a359b751 <unknown>
#9 0x55f7a3a70b4b <unknown>
#10 0x55f7a3a74929 <unknown>
#11 0x55f7a3a57929 <unknown>
#12 0x55f7a3a754e8 <unknown>
#13 0x55f7a3a3c0df <unknown>
#14 0x55f7a3a998e8 <unknown>
#15 0x55f7a3a99ac6 <unknown>
#16 0x55f7a3aab556 <unknown>
#17 0x73d5b5494ac3 <unknown>


[2025-07-12 04:06:54] 
============================================================
[2025-07-12 04:06:54] FINAL STATISTICS
[2025-07-12 04:06:54] ============================================================
[2025-07-12 04:06:54] Total runs:                     1
[2025-07-12 04:06:54] Jobs Easy Applied:              0
[2025-07-12 04:06:54] External job links collected:   0
[2025-07-12 04:06:54]                               ----------
[2025-07-12 04:06:54] Total applied or collected:     0
[2025-07-12 04:06:54] 
Failed jobs:                    0
[2025-07-12 04:06:54] Irrelevant jobs skipped:        0
[2025-07-12 04:06:54] 
Whether you think you can or you think you can't, you're right. - Henry Ford

Best regards : )
[2025-07-12 04:06:56] Browser closed successfully
[2025-07-12 04:08:45] üìÅ Directory already exists: all excels
[2025-07-12 04:08:45] üìÅ Directory already exists: all excels
[2025-07-12 04:08:45] üìÅ Directory already exists: logs/screenshots
[2025-07-12 04:08:45] üìÅ Directory already exists: all resumes/default
[2025-07-12 04:08:45] üìÅ Directory already exists: all resumes/temp
[2025-07-12 04:08:45] IF YOU HAVE MORE THAN 10 TABS OPENED, PLEASE CLOSE OR BOOKMARK THEM!
[2025-07-12 04:08:45] SAFE MODE: Using guest profile, no history saved!
[2025-07-12 04:08:48] üìÅ Directory already exists: all excels
[2025-07-12 04:08:48] üìÅ Directory already exists: all excels
[2025-07-12 04:08:48] üìÅ Directory already exists: logs/screenshots
[2025-07-12 04:08:48] üìÅ Directory already exists: all resumes/default
[2025-07-12 04:08:48] üìÅ Directory already exists: all resumes/temp
[2025-07-12 04:08:48] IF YOU HAVE MORE THAN 10 TABS OPENED, PLEASE CLOSE OR BOOKMARK THEM!
[2025-07-12 04:08:48] SAFE MODE: Using guest profile, no history saved!
[2025-07-12 04:09:13] [ERROR] Unknown: Could not find link with text: 'Sign in'
Traceback (most recent call last):
  File "/home/wagle/garbageGold/app/linkedinBot/browser/clickers_and_finders.py", line 264, in try_linkText
    element = driver.find_element(By.LINK_TEXT, linkText)
  File "/home/wagle/garbageGold/.venv/lib/python3.13/site-packages/selenium/webdriver/remote/webdriver.py", line 748, in find_element
    return self.execute(Command.FIND_ELEMENT, {"using": by, "value": value})["value"]
           ~~~~~~~~~~~~^^^^^^^^^^^^^^^^^^^^^^^^^^^^^^^^^^^^^^^^^^^^^^^^^^^^^
  File "/home/wagle/garbageGold/.venv/lib/python3.13/site-packages/selenium/webdriver/remote/webdriver.py", line 354, in execute
    self.error_handler.check_response(response)
    ~~~~~~~~~~~~~~~~~~~~~~~~~~~~~~~~~^^^^^^^^^^
  File "/home/wagle/garbageGold/.venv/lib/python3.13/site-packages/selenium/webdriver/remote/errorhandler.py", line 229, in check_response
    raise exception_class(message, screen, stacktrace)
selenium.common.exceptions.NoSuchElementException: Message: no such element: Unable to locate element: {"method":"link text","selector":"Sign in"}
  (Session info: chrome=138.0.7204.49); For documentation on this error, please visit: https://www.selenium.dev/documentation/webdriver/troubleshooting/errors#no-such-element-exception
Stacktrace:
#0 0x64eb81b7d23a <unknown>
#1 0x64eb81627ab0 <unknown>
#2 0x64eb816796f0 <unknown>
#3 0x64eb816798e1 <unknown>
#4 0x64eb816c7b94 <unknown>
#5 0x64eb8169f1cd <unknown>
#6 0x64eb816c4fee <unknown>
#7 0x64eb8169ef73 <unknown>
#8 0x64eb8166baeb <unknown>
#9 0x64eb8166c751 <unknown>
#10 0x64eb81b41b4b <unknown>
#11 0x64eb81b45929 <unknown>
#12 0x64eb81b28929 <unknown>
#13 0x64eb81b464e8 <unknown>
#14 0x64eb81b0d0df <unknown>
#15 0x64eb81b6a8e8 <unknown>
#16 0x64eb81b6aac6 <unknown>
#17 0x64eb81b7c556 <unknown>
#18 0x72fe2f494ac3 <unknown>


[2025-07-12 04:09:13] [ERROR] Unknown: Could not find element with xpath: '//button[@type="submit" and contains(text(), "Sign in")]'
Traceback (most recent call last):
  File "/home/wagle/garbageGold/app/linkedinBot/browser/clickers_and_finders.py", line 236, in try_xp
    element = driver.find_element(By.XPATH, xpath)
  File "/home/wagle/garbageGold/.venv/lib/python3.13/site-packages/selenium/webdriver/remote/webdriver.py", line 748, in find_element
    return self.execute(Command.FIND_ELEMENT, {"using": by, "value": value})["value"]
           ~~~~~~~~~~~~^^^^^^^^^^^^^^^^^^^^^^^^^^^^^^^^^^^^^^^^^^^^^^^^^^^^^
  File "/home/wagle/garbageGold/.venv/lib/python3.13/site-packages/selenium/webdriver/remote/webdriver.py", line 354, in execute
    self.error_handler.check_response(response)
    ~~~~~~~~~~~~~~~~~~~~~~~~~~~~~~~~~^^^^^^^^^^
  File "/home/wagle/garbageGold/.venv/lib/python3.13/site-packages/selenium/webdriver/remote/errorhandler.py", line 229, in check_response
    raise exception_class(message, screen, stacktrace)
selenium.common.exceptions.NoSuchElementException: Message: no such element: Unable to locate element: {"method":"xpath","selector":"//button[@type="submit" and contains(text(), "Sign in")]"}
  (Session info: chrome=138.0.7204.49); For documentation on this error, please visit: https://www.selenium.dev/documentation/webdriver/troubleshooting/errors#no-such-element-exception
Stacktrace:
#0 0x64eb81b7d23a <unknown>
#1 0x64eb81627ab0 <unknown>
#2 0x64eb816796f0 <unknown>
#3 0x64eb816798e1 <unknown>
#4 0x64eb816c7b94 <unknown>
#5 0x64eb8169f1cd <unknown>
#6 0x64eb816c4fee <unknown>
#7 0x64eb8169ef73 <unknown>
#8 0x64eb8166baeb <unknown>
#9 0x64eb8166c751 <unknown>
#10 0x64eb81b41b4b <unknown>
#11 0x64eb81b45929 <unknown>
#12 0x64eb81b28929 <unknown>
#13 0x64eb81b464e8 <unknown>
#14 0x64eb81b0d0df <unknown>
#15 0x64eb81b6a8e8 <unknown>
#16 0x64eb81b6aac6 <unknown>
#17 0x64eb81b7c556 <unknown>
#18 0x72fe2f494ac3 <unknown>


[2025-07-12 04:09:13] [ERROR] Unknown: Could not find link with text: 'Join now'
Traceback (most recent call last):
  File "/home/wagle/garbageGold/app/linkedinBot/browser/clickers_and_finders.py", line 264, in try_linkText
    element = driver.find_element(By.LINK_TEXT, linkText)
  File "/home/wagle/garbageGold/.venv/lib/python3.13/site-packages/selenium/webdriver/remote/webdriver.py", line 748, in find_element
    return self.execute(Command.FIND_ELEMENT, {"using": by, "value": value})["value"]
           ~~~~~~~~~~~~^^^^^^^^^^^^^^^^^^^^^^^^^^^^^^^^^^^^^^^^^^^^^^^^^^^^^
  File "/home/wagle/garbageGold/.venv/lib/python3.13/site-packages/selenium/webdriver/remote/webdriver.py", line 354, in execute
    self.error_handler.check_response(response)
    ~~~~~~~~~~~~~~~~~~~~~~~~~~~~~~~~~^^^^^^^^^^
  File "/home/wagle/garbageGold/.venv/lib/python3.13/site-packages/selenium/webdriver/remote/errorhandler.py", line 229, in check_response
    raise exception_class(message, screen, stacktrace)
selenium.common.exceptions.NoSuchElementException: Message: no such element: Unable to locate element: {"method":"link text","selector":"Join now"}
  (Session info: chrome=138.0.7204.49); For documentation on this error, please visit: https://www.selenium.dev/documentation/webdriver/troubleshooting/errors#no-such-element-exception
Stacktrace:
#0 0x64eb81b7d23a <unknown>
#1 0x64eb81627ab0 <unknown>
#2 0x64eb816796f0 <unknown>
#3 0x64eb816798e1 <unknown>
#4 0x64eb816c7b94 <unknown>
#5 0x64eb8169f1cd <unknown>
#6 0x64eb816c4fee <unknown>
#7 0x64eb8169ef73 <unknown>
#8 0x64eb8166baeb <unknown>
#9 0x64eb8166c751 <unknown>
#10 0x64eb81b41b4b <unknown>
#11 0x64eb81b45929 <unknown>
#12 0x64eb81b28929 <unknown>
#13 0x64eb81b464e8 <unknown>
#14 0x64eb81b0d0df <unknown>
#15 0x64eb81b6a8e8 <unknown>
#16 0x64eb81b6aac6 <unknown>
#17 0x64eb81b7c556 <unknown>
#18 0x72fe2f494ac3 <unknown>


[2025-07-12 04:09:13] Didn't find Sign in link, so assuming user is logged in!
[2025-07-12 04:09:13] Initializing AI client for deepseek...
[2025-07-12 04:09:13] Creating DeepSeek client...
[2025-07-12 04:09:14] ‚úÖ DeepSeek client created
[2025-07-12 04:09:15] üîó API URL: https://api.deepseek.com
[2025-07-12 04:09:15] üß† Model: deepseek-chat
[2025-07-12 04:11:08] Starting continuous run with 10 search terms
[2025-07-12 04:11:08] 
====================================================================================================
[2025-07-12 04:11:08] Cycle 1 - 2025-07-12 04:11:08.522399
[2025-07-12 04:11:08] Looking for jobs posted within 'Past week' sorted by 'Most recent'
[2025-07-12 04:11:14] 
>>>> Now searching for ""Software Engineer"" <<<<

[2025-07-12 04:11:14] Setting search location as: "United States"
[2025-07-12 04:11:14] [ERROR] Unknown: Could not find element with xpath: './/input[@aria-label='City, state, or zip code'and not(@disabled)]'
Traceback (most recent call last):
  File "/home/wagle/garbageGold/app/linkedinBot/browser/clickers_and_finders.py", line 236, in try_xp
    element = driver.find_element(By.XPATH, xpath)
  File "/home/wagle/garbageGold/.venv/lib/python3.13/site-packages/selenium/webdriver/remote/webdriver.py", line 748, in find_element
    return self.execute(Command.FIND_ELEMENT, {"using": by, "value": value})["value"]
           ~~~~~~~~~~~~^^^^^^^^^^^^^^^^^^^^^^^^^^^^^^^^^^^^^^^^^^^^^^^^^^^^^
  File "/home/wagle/garbageGold/.venv/lib/python3.13/site-packages/selenium/webdriver/remote/webdriver.py", line 354, in execute
    self.error_handler.check_response(response)
    ~~~~~~~~~~~~~~~~~~~~~~~~~~~~~~~~~^^^^^^^^^^
  File "/home/wagle/garbageGold/.venv/lib/python3.13/site-packages/selenium/webdriver/remote/errorhandler.py", line 229, in check_response
    raise exception_class(message, screen, stacktrace)
selenium.common.exceptions.NoSuchElementException: Message: no such element: Unable to locate element: {"method":"xpath","selector":".//input[@aria-label='City, state, or zip code'and not(@disabled)]"}
  (Session info: chrome=138.0.7204.49); For documentation on this error, please visit: https://www.selenium.dev/documentation/webdriver/troubleshooting/errors#no-such-element-exception
Stacktrace:
#0 0x64eb81b7d23a <unknown>
#1 0x64eb81627ab0 <unknown>
#2 0x64eb816796f0 <unknown>
#3 0x64eb816798e1 <unknown>
#4 0x64eb816c7b94 <unknown>
#5 0x64eb8169f1cd <unknown>
#6 0x64eb816c4fee <unknown>
#7 0x64eb8169ef73 <unknown>
#8 0x64eb8166baeb <unknown>
#9 0x64eb8166c751 <unknown>
#10 0x64eb81b41b4b <unknown>
#11 0x64eb81b45929 <unknown>
#12 0x64eb81b28929 <unknown>
#13 0x64eb81b464e8 <unknown>
#14 0x64eb81b0d0df <unknown>
#15 0x64eb81b6a8e8 <unknown>
#16 0x64eb81b6aac6 <unknown>
#17 0x64eb81b7c556 <unknown>
#18 0x72fe2f494ac3 <unknown>


[2025-07-12 04:11:14] [ERROR] Unknown: Search Location input element was not provided!
NoneType: None

[2025-07-12 04:11:19] [ERROR] Unknown: Setting the preferences failed!
Traceback (most recent call last):
  File "/home/wagle/garbageGold/app/linkedinBot/job_filters/filters.py", line 23, in apply_filters
    wait.until(EC.presence_of_element_located((By.XPATH, '//button[normalize-space()="All filters"]'))).click()
    ~~~~~~~~~~^^^^^^^^^^^^^^^^^^^^^^^^^^^^^^^^^^^^^^^^^^^^^^^^^^^^^^^^^^^^^^^^^^^^^^^^^^^^^^^^^^^^^^^^^
  File "/home/wagle/garbageGold/.venv/lib/python3.13/site-packages/selenium/webdriver/support/wait.py", line 105, in until
    raise TimeoutException(message, screen, stacktrace)
selenium.common.exceptions.TimeoutException: Message: 
Stacktrace:
#0 0x64eb81b7d23a <unknown>
#1 0x64eb81627ab0 <unknown>
#2 0x64eb816796f0 <unknown>
#3 0x64eb816798e1 <unknown>
#4 0x64eb816c7b94 <unknown>
#5 0x64eb8169f1cd <unknown>
#6 0x64eb816c4fee <unknown>
#7 0x64eb8169ef73 <unknown>
#8 0x64eb8166baeb <unknown>
#9 0x64eb8166c751 <unknown>
#10 0x64eb81b41b4b <unknown>
#11 0x64eb81b45929 <unknown>
#12 0x64eb81b28929 <unknown>
#13 0x64eb81b464e8 <unknown>
#14 0x64eb81b0d0df <unknown>
#15 0x64eb81b6a8e8 <unknown>
#16 0x64eb81b6aac6 <unknown>
#17 0x64eb81b7c556 <unknown>
#18 0x72fe2f494ac3 <unknown>


[2025-07-12 04:11:24] Failed to process search term:
[2025-07-12 04:11:24] [ERROR] Message: 
: In process_search_term
Traceback (most recent call last):
  File "/home/wagle/garbageGold/app/linkedinBot/linkedinRun.py", line 572, in process_search_term
    self.wait.until(EC.presence_of_all_elements_located((By.XPATH, "//li[@data-occludable-job-id]")))
    ~~~~~~~~~~~~~~~^^^^^^^^^^^^^^^^^^^^^^^^^^^^^^^^^^^^^^^^^^^^^^^^^^^^^^^^^^^^^^^^^^^^^^^^^^^^^^^^^^
  File "/home/wagle/garbageGold/.venv/lib/python3.13/site-packages/selenium/webdriver/support/wait.py", line 105, in until
    raise TimeoutException(message, screen, stacktrace)
selenium.common.exceptions.TimeoutException: Message: 


[2025-07-12 04:11:24] Processed 0 jobs for search term: "Software Engineer"
[2025-07-12 04:11:27] 
>>>> Now searching for ""Software Developer"" <<<<

[2025-07-12 04:11:27] Setting search location as: "United States"
[2025-07-12 04:11:27] [ERROR] Unknown: Could not find element with xpath: './/input[@aria-label='City, state, or zip code'and not(@disabled)]'
Traceback (most recent call last):
  File "/home/wagle/garbageGold/app/linkedinBot/browser/clickers_and_finders.py", line 236, in try_xp
    element = driver.find_element(By.XPATH, xpath)
  File "/home/wagle/garbageGold/.venv/lib/python3.13/site-packages/selenium/webdriver/remote/webdriver.py", line 748, in find_element
    return self.execute(Command.FIND_ELEMENT, {"using": by, "value": value})["value"]
           ~~~~~~~~~~~~^^^^^^^^^^^^^^^^^^^^^^^^^^^^^^^^^^^^^^^^^^^^^^^^^^^^^
  File "/home/wagle/garbageGold/.venv/lib/python3.13/site-packages/selenium/webdriver/remote/webdriver.py", line 354, in execute
    self.error_handler.check_response(response)
    ~~~~~~~~~~~~~~~~~~~~~~~~~~~~~~~~~^^^^^^^^^^
  File "/home/wagle/garbageGold/.venv/lib/python3.13/site-packages/selenium/webdriver/remote/errorhandler.py", line 229, in check_response
    raise exception_class(message, screen, stacktrace)
selenium.common.exceptions.NoSuchElementException: Message: no such element: Unable to locate element: {"method":"xpath","selector":".//input[@aria-label='City, state, or zip code'and not(@disabled)]"}
  (Session info: chrome=138.0.7204.49); For documentation on this error, please visit: https://www.selenium.dev/documentation/webdriver/troubleshooting/errors#no-such-element-exception
Stacktrace:
#0 0x64eb81b7d23a <unknown>
#1 0x64eb81627ab0 <unknown>
#2 0x64eb816796f0 <unknown>
#3 0x64eb816798e1 <unknown>
#4 0x64eb816c7b94 <unknown>
#5 0x64eb8169f1cd <unknown>
#6 0x64eb816c4fee <unknown>
#7 0x64eb8169ef73 <unknown>
#8 0x64eb8166baeb <unknown>
#9 0x64eb8166c751 <unknown>
#10 0x64eb81b41b4b <unknown>
#11 0x64eb81b45929 <unknown>
#12 0x64eb81b28929 <unknown>
#13 0x64eb81b464e8 <unknown>
#14 0x64eb81b0d0df <unknown>
#15 0x64eb81b6a8e8 <unknown>
#16 0x64eb81b6aac6 <unknown>
#17 0x64eb81b7c556 <unknown>
#18 0x72fe2f494ac3 <unknown>


[2025-07-12 04:11:27] [ERROR] Unknown: Search Location input element was not provided!
NoneType: None

[2025-07-12 04:11:32] [ERROR] Unknown: Setting the preferences failed!
Traceback (most recent call last):
  File "/home/wagle/garbageGold/app/linkedinBot/job_filters/filters.py", line 23, in apply_filters
    wait.until(EC.presence_of_element_located((By.XPATH, '//button[normalize-space()="All filters"]'))).click()
    ~~~~~~~~~~^^^^^^^^^^^^^^^^^^^^^^^^^^^^^^^^^^^^^^^^^^^^^^^^^^^^^^^^^^^^^^^^^^^^^^^^^^^^^^^^^^^^^^^^^
  File "/home/wagle/garbageGold/.venv/lib/python3.13/site-packages/selenium/webdriver/support/wait.py", line 105, in until
    raise TimeoutException(message, screen, stacktrace)
selenium.common.exceptions.TimeoutException: Message: 
Stacktrace:
#0 0x64eb81b7d23a <unknown>
#1 0x64eb81627ab0 <unknown>
#2 0x64eb816796f0 <unknown>
#3 0x64eb816798e1 <unknown>
#4 0x64eb816c7b94 <unknown>
#5 0x64eb8169f1cd <unknown>
#6 0x64eb816c4fee <unknown>
#7 0x64eb8169ef73 <unknown>
#8 0x64eb8166baeb <unknown>
#9 0x64eb8166c751 <unknown>
#10 0x64eb81b41b4b <unknown>
#11 0x64eb81b45929 <unknown>
#12 0x64eb81b28929 <unknown>
#13 0x64eb81b464e8 <unknown>
#14 0x64eb81b0d0df <unknown>
#15 0x64eb81b6a8e8 <unknown>
#16 0x64eb81b6aac6 <unknown>
#17 0x64eb81b7c556 <unknown>
#18 0x72fe2f494ac3 <unknown>


[2025-07-12 04:11:37] Failed to process search term:
[2025-07-12 04:11:37] [ERROR] Message: 
: In process_search_term
Traceback (most recent call last):
  File "/home/wagle/garbageGold/app/linkedinBot/linkedinRun.py", line 572, in process_search_term
    self.wait.until(EC.presence_of_all_elements_located((By.XPATH, "//li[@data-occludable-job-id]")))
    ~~~~~~~~~~~~~~~^^^^^^^^^^^^^^^^^^^^^^^^^^^^^^^^^^^^^^^^^^^^^^^^^^^^^^^^^^^^^^^^^^^^^^^^^^^^^^^^^^
  File "/home/wagle/garbageGold/.venv/lib/python3.13/site-packages/selenium/webdriver/support/wait.py", line 105, in until
    raise TimeoutException(message, screen, stacktrace)
selenium.common.exceptions.TimeoutException: Message: 


[2025-07-12 04:11:37] Processed 0 jobs for search term: "Software Developer"
[2025-07-12 04:11:39] 
>>>> Now searching for ""Python Developer"" <<<<

[2025-07-12 04:11:39] Setting search location as: "United States"
[2025-07-12 04:11:39] [ERROR] Unknown: Could not find element with xpath: './/input[@aria-label='City, state, or zip code'and not(@disabled)]'
Traceback (most recent call last):
  File "/home/wagle/garbageGold/app/linkedinBot/browser/clickers_and_finders.py", line 236, in try_xp
    element = driver.find_element(By.XPATH, xpath)
  File "/home/wagle/garbageGold/.venv/lib/python3.13/site-packages/selenium/webdriver/remote/webdriver.py", line 748, in find_element
    return self.execute(Command.FIND_ELEMENT, {"using": by, "value": value})["value"]
           ~~~~~~~~~~~~^^^^^^^^^^^^^^^^^^^^^^^^^^^^^^^^^^^^^^^^^^^^^^^^^^^^^
  File "/home/wagle/garbageGold/.venv/lib/python3.13/site-packages/selenium/webdriver/remote/webdriver.py", line 354, in execute
    self.error_handler.check_response(response)
    ~~~~~~~~~~~~~~~~~~~~~~~~~~~~~~~~~^^^^^^^^^^
  File "/home/wagle/garbageGold/.venv/lib/python3.13/site-packages/selenium/webdriver/remote/errorhandler.py", line 229, in check_response
    raise exception_class(message, screen, stacktrace)
selenium.common.exceptions.NoSuchElementException: Message: no such element: Unable to locate element: {"method":"xpath","selector":".//input[@aria-label='City, state, or zip code'and not(@disabled)]"}
  (Session info: chrome=138.0.7204.49); For documentation on this error, please visit: https://www.selenium.dev/documentation/webdriver/troubleshooting/errors#no-such-element-exception
Stacktrace:
#0 0x64eb81b7d23a <unknown>
#1 0x64eb81627ab0 <unknown>
#2 0x64eb816796f0 <unknown>
#3 0x64eb816798e1 <unknown>
#4 0x64eb816c7b94 <unknown>
#5 0x64eb8169f1cd <unknown>
#6 0x64eb816c4fee <unknown>
#7 0x64eb8169ef73 <unknown>
#8 0x64eb8166baeb <unknown>
#9 0x64eb8166c751 <unknown>
#10 0x64eb81b41b4b <unknown>
#11 0x64eb81b45929 <unknown>
#12 0x64eb81b28929 <unknown>
#13 0x64eb81b464e8 <unknown>
#14 0x64eb81b0d0df <unknown>
#15 0x64eb81b6a8e8 <unknown>
#16 0x64eb81b6aac6 <unknown>
#17 0x64eb81b7c556 <unknown>
#18 0x72fe2f494ac3 <unknown>


[2025-07-12 04:11:39] [ERROR] Unknown: Search Location input element was not provided!
NoneType: None

[2025-07-12 04:11:44] [ERROR] Unknown: Setting the preferences failed!
Traceback (most recent call last):
  File "/home/wagle/garbageGold/app/linkedinBot/job_filters/filters.py", line 23, in apply_filters
    wait.until(EC.presence_of_element_located((By.XPATH, '//button[normalize-space()="All filters"]'))).click()
    ~~~~~~~~~~^^^^^^^^^^^^^^^^^^^^^^^^^^^^^^^^^^^^^^^^^^^^^^^^^^^^^^^^^^^^^^^^^^^^^^^^^^^^^^^^^^^^^^^^^
  File "/home/wagle/garbageGold/.venv/lib/python3.13/site-packages/selenium/webdriver/support/wait.py", line 105, in until
    raise TimeoutException(message, screen, stacktrace)
selenium.common.exceptions.TimeoutException: Message: 
Stacktrace:
#0 0x64eb81b7d23a <unknown>
#1 0x64eb81627ab0 <unknown>
#2 0x64eb816796f0 <unknown>
#3 0x64eb816798e1 <unknown>
#4 0x64eb816c7b94 <unknown>
#5 0x64eb8169f1cd <unknown>
#6 0x64eb816c4fee <unknown>
#7 0x64eb8169ef73 <unknown>
#8 0x64eb8166baeb <unknown>
#9 0x64eb8166c751 <unknown>
#10 0x64eb81b41b4b <unknown>
#11 0x64eb81b45929 <unknown>
#12 0x64eb81b28929 <unknown>
#13 0x64eb81b464e8 <unknown>
#14 0x64eb81b0d0df <unknown>
#15 0x64eb81b6a8e8 <unknown>
#16 0x64eb81b6aac6 <unknown>
#17 0x64eb81b7c556 <unknown>
#18 0x72fe2f494ac3 <unknown>


[2025-07-12 04:11:49] Failed to process search term:
[2025-07-12 04:11:49] [ERROR] Message: 
: In process_search_term
Traceback (most recent call last):
  File "/home/wagle/garbageGold/app/linkedinBot/linkedinRun.py", line 572, in process_search_term
    self.wait.until(EC.presence_of_all_elements_located((By.XPATH, "//li[@data-occludable-job-id]")))
    ~~~~~~~~~~~~~~~^^^^^^^^^^^^^^^^^^^^^^^^^^^^^^^^^^^^^^^^^^^^^^^^^^^^^^^^^^^^^^^^^^^^^^^^^^^^^^^^^^
  File "/home/wagle/garbageGold/.venv/lib/python3.13/site-packages/selenium/webdriver/support/wait.py", line 105, in until
    raise TimeoutException(message, screen, stacktrace)
selenium.common.exceptions.TimeoutException: Message: 


[2025-07-12 04:11:49] Processed 0 jobs for search term: "Python Developer"
[2025-07-12 04:11:50] 
>>>> Now searching for ""Selenium Developer"" <<<<

[2025-07-12 04:11:50] Setting search location as: "United States"
[2025-07-12 04:11:50] [ERROR] Unknown: Could not find element with xpath: './/input[@aria-label='City, state, or zip code'and not(@disabled)]'
Traceback (most recent call last):
  File "/home/wagle/garbageGold/app/linkedinBot/browser/clickers_and_finders.py", line 236, in try_xp
    element = driver.find_element(By.XPATH, xpath)
  File "/home/wagle/garbageGold/.venv/lib/python3.13/site-packages/selenium/webdriver/remote/webdriver.py", line 748, in find_element
    return self.execute(Command.FIND_ELEMENT, {"using": by, "value": value})["value"]
           ~~~~~~~~~~~~^^^^^^^^^^^^^^^^^^^^^^^^^^^^^^^^^^^^^^^^^^^^^^^^^^^^^
  File "/home/wagle/garbageGold/.venv/lib/python3.13/site-packages/selenium/webdriver/remote/webdriver.py", line 354, in execute
    self.error_handler.check_response(response)
    ~~~~~~~~~~~~~~~~~~~~~~~~~~~~~~~~~^^^^^^^^^^
  File "/home/wagle/garbageGold/.venv/lib/python3.13/site-packages/selenium/webdriver/remote/errorhandler.py", line 229, in check_response
    raise exception_class(message, screen, stacktrace)
selenium.common.exceptions.NoSuchElementException: Message: no such element: Unable to locate element: {"method":"xpath","selector":".//input[@aria-label='City, state, or zip code'and not(@disabled)]"}
  (Session info: chrome=138.0.7204.49); For documentation on this error, please visit: https://www.selenium.dev/documentation/webdriver/troubleshooting/errors#no-such-element-exception
Stacktrace:
#0 0x64eb81b7d23a <unknown>
#1 0x64eb81627ab0 <unknown>
#2 0x64eb816796f0 <unknown>
#3 0x64eb816798e1 <unknown>
#4 0x64eb816c7b94 <unknown>
#5 0x64eb8169f1cd <unknown>
#6 0x64eb816c4fee <unknown>
#7 0x64eb8169ef73 <unknown>
#8 0x64eb8166baeb <unknown>
#9 0x64eb8166c751 <unknown>
#10 0x64eb81b41b4b <unknown>
#11 0x64eb81b45929 <unknown>
#12 0x64eb81b28929 <unknown>
#13 0x64eb81b464e8 <unknown>
#14 0x64eb81b0d0df <unknown>
#15 0x64eb81b6a8e8 <unknown>
#16 0x64eb81b6aac6 <unknown>
#17 0x64eb81b7c556 <unknown>
#18 0x72fe2f494ac3 <unknown>


[2025-07-12 04:11:50] [ERROR] Unknown: Search Location input element was not provided!
NoneType: None

[2025-07-12 04:11:55] [ERROR] Unknown: Setting the preferences failed!
Traceback (most recent call last):
  File "/home/wagle/garbageGold/app/linkedinBot/job_filters/filters.py", line 23, in apply_filters
    wait.until(EC.presence_of_element_located((By.XPATH, '//button[normalize-space()="All filters"]'))).click()
    ~~~~~~~~~~^^^^^^^^^^^^^^^^^^^^^^^^^^^^^^^^^^^^^^^^^^^^^^^^^^^^^^^^^^^^^^^^^^^^^^^^^^^^^^^^^^^^^^^^^
  File "/home/wagle/garbageGold/.venv/lib/python3.13/site-packages/selenium/webdriver/support/wait.py", line 105, in until
    raise TimeoutException(message, screen, stacktrace)
selenium.common.exceptions.TimeoutException: Message: 
Stacktrace:
#0 0x64eb81b7d23a <unknown>
#1 0x64eb81627ab0 <unknown>
#2 0x64eb816796f0 <unknown>
#3 0x64eb816798e1 <unknown>
#4 0x64eb816c7b94 <unknown>
#5 0x64eb8169f1cd <unknown>
#6 0x64eb816c4fee <unknown>
#7 0x64eb8169ef73 <unknown>
#8 0x64eb8166baeb <unknown>
#9 0x64eb8166c751 <unknown>
#10 0x64eb81b41b4b <unknown>
#11 0x64eb81b45929 <unknown>
#12 0x64eb81b28929 <unknown>
#13 0x64eb81b464e8 <unknown>
#14 0x64eb81b0d0df <unknown>
#15 0x64eb81b6a8e8 <unknown>
#16 0x64eb81b6aac6 <unknown>
#17 0x64eb81b7c556 <unknown>
#18 0x72fe2f494ac3 <unknown>


[2025-07-12 04:12:00] Failed to process search term:
[2025-07-12 04:12:00] [ERROR] Message: 
: In process_search_term
Traceback (most recent call last):
  File "/home/wagle/garbageGold/app/linkedinBot/linkedinRun.py", line 572, in process_search_term
    self.wait.until(EC.presence_of_all_elements_located((By.XPATH, "//li[@data-occludable-job-id]")))
    ~~~~~~~~~~~~~~~^^^^^^^^^^^^^^^^^^^^^^^^^^^^^^^^^^^^^^^^^^^^^^^^^^^^^^^^^^^^^^^^^^^^^^^^^^^^^^^^^^
  File "/home/wagle/garbageGold/.venv/lib/python3.13/site-packages/selenium/webdriver/support/wait.py", line 105, in until
    raise TimeoutException(message, screen, stacktrace)
selenium.common.exceptions.TimeoutException: Message: 


[2025-07-12 04:12:00] Processed 0 jobs for search term: "Selenium Developer"
[2025-07-12 04:12:01] 
>>>> Now searching for ""React Developer"" <<<<

[2025-07-12 04:12:01] Setting search location as: "United States"
[2025-07-12 04:12:01] [ERROR] Unknown: Could not find element with xpath: './/input[@aria-label='City, state, or zip code'and not(@disabled)]'
Traceback (most recent call last):
  File "/home/wagle/garbageGold/app/linkedinBot/browser/clickers_and_finders.py", line 236, in try_xp
    element = driver.find_element(By.XPATH, xpath)
  File "/home/wagle/garbageGold/.venv/lib/python3.13/site-packages/selenium/webdriver/remote/webdriver.py", line 748, in find_element
    return self.execute(Command.FIND_ELEMENT, {"using": by, "value": value})["value"]
           ~~~~~~~~~~~~^^^^^^^^^^^^^^^^^^^^^^^^^^^^^^^^^^^^^^^^^^^^^^^^^^^^^
  File "/home/wagle/garbageGold/.venv/lib/python3.13/site-packages/selenium/webdriver/remote/webdriver.py", line 354, in execute
    self.error_handler.check_response(response)
    ~~~~~~~~~~~~~~~~~~~~~~~~~~~~~~~~~^^^^^^^^^^
  File "/home/wagle/garbageGold/.venv/lib/python3.13/site-packages/selenium/webdriver/remote/errorhandler.py", line 229, in check_response
    raise exception_class(message, screen, stacktrace)
selenium.common.exceptions.NoSuchElementException: Message: no such element: Unable to locate element: {"method":"xpath","selector":".//input[@aria-label='City, state, or zip code'and not(@disabled)]"}
  (Session info: chrome=138.0.7204.49); For documentation on this error, please visit: https://www.selenium.dev/documentation/webdriver/troubleshooting/errors#no-such-element-exception
Stacktrace:
#0 0x64eb81b7d23a <unknown>
#1 0x64eb81627ab0 <unknown>
#2 0x64eb816796f0 <unknown>
#3 0x64eb816798e1 <unknown>
#4 0x64eb816c7b94 <unknown>
#5 0x64eb8169f1cd <unknown>
#6 0x64eb816c4fee <unknown>
#7 0x64eb8169ef73 <unknown>
#8 0x64eb8166baeb <unknown>
#9 0x64eb8166c751 <unknown>
#10 0x64eb81b41b4b <unknown>
#11 0x64eb81b45929 <unknown>
#12 0x64eb81b28929 <unknown>
#13 0x64eb81b464e8 <unknown>
#14 0x64eb81b0d0df <unknown>
#15 0x64eb81b6a8e8 <unknown>
#16 0x64eb81b6aac6 <unknown>
#17 0x64eb81b7c556 <unknown>
#18 0x72fe2f494ac3 <unknown>


[2025-07-12 04:12:01] [ERROR] Unknown: Search Location input element was not provided!
NoneType: None

[2025-07-12 04:12:07] [ERROR] Unknown: Setting the preferences failed!
Traceback (most recent call last):
  File "/home/wagle/garbageGold/app/linkedinBot/job_filters/filters.py", line 23, in apply_filters
    wait.until(EC.presence_of_element_located((By.XPATH, '//button[normalize-space()="All filters"]'))).click()
    ~~~~~~~~~~^^^^^^^^^^^^^^^^^^^^^^^^^^^^^^^^^^^^^^^^^^^^^^^^^^^^^^^^^^^^^^^^^^^^^^^^^^^^^^^^^^^^^^^^^
  File "/home/wagle/garbageGold/.venv/lib/python3.13/site-packages/selenium/webdriver/support/wait.py", line 105, in until
    raise TimeoutException(message, screen, stacktrace)
selenium.common.exceptions.TimeoutException: Message: 
Stacktrace:
#0 0x64eb81b7d23a <unknown>
#1 0x64eb81627ab0 <unknown>
#2 0x64eb816796f0 <unknown>
#3 0x64eb816798e1 <unknown>
#4 0x64eb816c7b94 <unknown>
#5 0x64eb8169f1cd <unknown>
#6 0x64eb816c4fee <unknown>
#7 0x64eb8169ef73 <unknown>
#8 0x64eb8166baeb <unknown>
#9 0x64eb8166c751 <unknown>
#10 0x64eb81b41b4b <unknown>
#11 0x64eb81b45929 <unknown>
#12 0x64eb81b28929 <unknown>
#13 0x64eb81b464e8 <unknown>
#14 0x64eb81b0d0df <unknown>
#15 0x64eb81b6a8e8 <unknown>
#16 0x64eb81b6aac6 <unknown>
#17 0x64eb81b7c556 <unknown>
#18 0x72fe2f494ac3 <unknown>


[2025-07-12 04:12:12] Failed to process search term:
[2025-07-12 04:12:12] [ERROR] Message: 
: In process_search_term
Traceback (most recent call last):
  File "/home/wagle/garbageGold/app/linkedinBot/linkedinRun.py", line 572, in process_search_term
    self.wait.until(EC.presence_of_all_elements_located((By.XPATH, "//li[@data-occludable-job-id]")))
    ~~~~~~~~~~~~~~~^^^^^^^^^^^^^^^^^^^^^^^^^^^^^^^^^^^^^^^^^^^^^^^^^^^^^^^^^^^^^^^^^^^^^^^^^^^^^^^^^^
  File "/home/wagle/garbageGold/.venv/lib/python3.13/site-packages/selenium/webdriver/support/wait.py", line 105, in until
    raise TimeoutException(message, screen, stacktrace)
selenium.common.exceptions.TimeoutException: Message: 


[2025-07-12 04:12:12] Processed 0 jobs for search term: "React Developer"
[2025-07-12 04:12:13] 
>>>> Now searching for ""Java Developer"" <<<<

[2025-07-12 04:12:13] Setting search location as: "United States"
[2025-07-12 04:12:13] [ERROR] Unknown: Could not find element with xpath: './/input[@aria-label='City, state, or zip code'and not(@disabled)]'
Traceback (most recent call last):
  File "/home/wagle/garbageGold/app/linkedinBot/browser/clickers_and_finders.py", line 236, in try_xp
    element = driver.find_element(By.XPATH, xpath)
  File "/home/wagle/garbageGold/.venv/lib/python3.13/site-packages/selenium/webdriver/remote/webdriver.py", line 748, in find_element
    return self.execute(Command.FIND_ELEMENT, {"using": by, "value": value})["value"]
           ~~~~~~~~~~~~^^^^^^^^^^^^^^^^^^^^^^^^^^^^^^^^^^^^^^^^^^^^^^^^^^^^^
  File "/home/wagle/garbageGold/.venv/lib/python3.13/site-packages/selenium/webdriver/remote/webdriver.py", line 354, in execute
    self.error_handler.check_response(response)
    ~~~~~~~~~~~~~~~~~~~~~~~~~~~~~~~~~^^^^^^^^^^
  File "/home/wagle/garbageGold/.venv/lib/python3.13/site-packages/selenium/webdriver/remote/errorhandler.py", line 229, in check_response
    raise exception_class(message, screen, stacktrace)
selenium.common.exceptions.NoSuchElementException: Message: no such element: Unable to locate element: {"method":"xpath","selector":".//input[@aria-label='City, state, or zip code'and not(@disabled)]"}
  (Session info: chrome=138.0.7204.49); For documentation on this error, please visit: https://www.selenium.dev/documentation/webdriver/troubleshooting/errors#no-such-element-exception
Stacktrace:
#0 0x64eb81b7d23a <unknown>
#1 0x64eb81627ab0 <unknown>
#2 0x64eb816796f0 <unknown>
#3 0x64eb816798e1 <unknown>
#4 0x64eb816c7b94 <unknown>
#5 0x64eb8169f1cd <unknown>
#6 0x64eb816c4fee <unknown>
#7 0x64eb8169ef73 <unknown>
#8 0x64eb8166baeb <unknown>
#9 0x64eb8166c751 <unknown>
#10 0x64eb81b41b4b <unknown>
#11 0x64eb81b45929 <unknown>
#12 0x64eb81b28929 <unknown>
#13 0x64eb81b464e8 <unknown>
#14 0x64eb81b0d0df <unknown>
#15 0x64eb81b6a8e8 <unknown>
#16 0x64eb81b6aac6 <unknown>
#17 0x64eb81b7c556 <unknown>
#18 0x72fe2f494ac3 <unknown>


[2025-07-12 04:12:13] [ERROR] Unknown: Search Location input element was not provided!
NoneType: None

[2025-07-12 04:12:18] [ERROR] Unknown: Setting the preferences failed!
Traceback (most recent call last):
  File "/home/wagle/garbageGold/app/linkedinBot/job_filters/filters.py", line 23, in apply_filters
    wait.until(EC.presence_of_element_located((By.XPATH, '//button[normalize-space()="All filters"]'))).click()
    ~~~~~~~~~~^^^^^^^^^^^^^^^^^^^^^^^^^^^^^^^^^^^^^^^^^^^^^^^^^^^^^^^^^^^^^^^^^^^^^^^^^^^^^^^^^^^^^^^^^
  File "/home/wagle/garbageGold/.venv/lib/python3.13/site-packages/selenium/webdriver/support/wait.py", line 105, in until
    raise TimeoutException(message, screen, stacktrace)
selenium.common.exceptions.TimeoutException: Message: 
Stacktrace:
#0 0x64eb81b7d23a <unknown>
#1 0x64eb81627ab0 <unknown>
#2 0x64eb816796f0 <unknown>
#3 0x64eb816798e1 <unknown>
#4 0x64eb816c7b94 <unknown>
#5 0x64eb8169f1cd <unknown>
#6 0x64eb816c4fee <unknown>
#7 0x64eb8169ef73 <unknown>
#8 0x64eb8166baeb <unknown>
#9 0x64eb8166c751 <unknown>
#10 0x64eb81b41b4b <unknown>
#11 0x64eb81b45929 <unknown>
#12 0x64eb81b28929 <unknown>
#13 0x64eb81b464e8 <unknown>
#14 0x64eb81b0d0df <unknown>
#15 0x64eb81b6a8e8 <unknown>
#16 0x64eb81b6aac6 <unknown>
#17 0x64eb81b7c556 <unknown>
#18 0x72fe2f494ac3 <unknown>


[2025-07-12 04:12:24] Failed to process search term:
[2025-07-12 04:12:24] [ERROR] Message: 
: In process_search_term
Traceback (most recent call last):
  File "/home/wagle/garbageGold/app/linkedinBot/linkedinRun.py", line 572, in process_search_term
    self.wait.until(EC.presence_of_all_elements_located((By.XPATH, "//li[@data-occludable-job-id]")))
    ~~~~~~~~~~~~~~~^^^^^^^^^^^^^^^^^^^^^^^^^^^^^^^^^^^^^^^^^^^^^^^^^^^^^^^^^^^^^^^^^^^^^^^^^^^^^^^^^^
  File "/home/wagle/garbageGold/.venv/lib/python3.13/site-packages/selenium/webdriver/support/wait.py", line 105, in until
    raise TimeoutException(message, screen, stacktrace)
selenium.common.exceptions.TimeoutException: Message: 


[2025-07-12 04:12:24] Processed 0 jobs for search term: "Java Developer"
[2025-07-12 04:12:25] 
>>>> Now searching for ""Front End Developer"" <<<<

[2025-07-12 04:12:25] Setting search location as: "United States"
[2025-07-12 04:12:25] [ERROR] Unknown: Could not find element with xpath: './/input[@aria-label='City, state, or zip code'and not(@disabled)]'
Traceback (most recent call last):
  File "/home/wagle/garbageGold/app/linkedinBot/browser/clickers_and_finders.py", line 236, in try_xp
    element = driver.find_element(By.XPATH, xpath)
  File "/home/wagle/garbageGold/.venv/lib/python3.13/site-packages/selenium/webdriver/remote/webdriver.py", line 748, in find_element
    return self.execute(Command.FIND_ELEMENT, {"using": by, "value": value})["value"]
           ~~~~~~~~~~~~^^^^^^^^^^^^^^^^^^^^^^^^^^^^^^^^^^^^^^^^^^^^^^^^^^^^^
  File "/home/wagle/garbageGold/.venv/lib/python3.13/site-packages/selenium/webdriver/remote/webdriver.py", line 354, in execute
    self.error_handler.check_response(response)
    ~~~~~~~~~~~~~~~~~~~~~~~~~~~~~~~~~^^^^^^^^^^
  File "/home/wagle/garbageGold/.venv/lib/python3.13/site-packages/selenium/webdriver/remote/errorhandler.py", line 229, in check_response
    raise exception_class(message, screen, stacktrace)
selenium.common.exceptions.NoSuchElementException: Message: no such element: Unable to locate element: {"method":"xpath","selector":".//input[@aria-label='City, state, or zip code'and not(@disabled)]"}
  (Session info: chrome=138.0.7204.49); For documentation on this error, please visit: https://www.selenium.dev/documentation/webdriver/troubleshooting/errors#no-such-element-exception
Stacktrace:
#0 0x64eb81b7d23a <unknown>
#1 0x64eb81627ab0 <unknown>
#2 0x64eb816796f0 <unknown>
#3 0x64eb816798e1 <unknown>
#4 0x64eb816c7b94 <unknown>
#5 0x64eb8169f1cd <unknown>
#6 0x64eb816c4fee <unknown>
#7 0x64eb8169ef73 <unknown>
#8 0x64eb8166baeb <unknown>
#9 0x64eb8166c751 <unknown>
#10 0x64eb81b41b4b <unknown>
#11 0x64eb81b45929 <unknown>
#12 0x64eb81b28929 <unknown>
#13 0x64eb81b464e8 <unknown>
#14 0x64eb81b0d0df <unknown>
#15 0x64eb81b6a8e8 <unknown>
#16 0x64eb81b6aac6 <unknown>
#17 0x64eb81b7c556 <unknown>
#18 0x72fe2f494ac3 <unknown>


[2025-07-12 04:12:25] [ERROR] Unknown: Search Location input element was not provided!
NoneType: None

[2025-07-12 04:12:30] [ERROR] Unknown: Setting the preferences failed!
Traceback (most recent call last):
  File "/home/wagle/garbageGold/app/linkedinBot/job_filters/filters.py", line 23, in apply_filters
    wait.until(EC.presence_of_element_located((By.XPATH, '//button[normalize-space()="All filters"]'))).click()
    ~~~~~~~~~~^^^^^^^^^^^^^^^^^^^^^^^^^^^^^^^^^^^^^^^^^^^^^^^^^^^^^^^^^^^^^^^^^^^^^^^^^^^^^^^^^^^^^^^^^
  File "/home/wagle/garbageGold/.venv/lib/python3.13/site-packages/selenium/webdriver/support/wait.py", line 105, in until
    raise TimeoutException(message, screen, stacktrace)
selenium.common.exceptions.TimeoutException: Message: 
Stacktrace:
#0 0x64eb81b7d23a <unknown>
#1 0x64eb81627ab0 <unknown>
#2 0x64eb816796f0 <unknown>
#3 0x64eb816798e1 <unknown>
#4 0x64eb816c7b94 <unknown>
#5 0x64eb8169f1cd <unknown>
#6 0x64eb816c4fee <unknown>
#7 0x64eb8169ef73 <unknown>
#8 0x64eb8166baeb <unknown>
#9 0x64eb8166c751 <unknown>
#10 0x64eb81b41b4b <unknown>
#11 0x64eb81b45929 <unknown>
#12 0x64eb81b28929 <unknown>
#13 0x64eb81b464e8 <unknown>
#14 0x64eb81b0d0df <unknown>
#15 0x64eb81b6a8e8 <unknown>
#16 0x64eb81b6aac6 <unknown>
#17 0x64eb81b7c556 <unknown>
#18 0x72fe2f494ac3 <unknown>


[2025-07-12 04:12:35] Failed to process search term:
[2025-07-12 04:12:35] [ERROR] Message: 
: In process_search_term
Traceback (most recent call last):
  File "/home/wagle/garbageGold/app/linkedinBot/linkedinRun.py", line 572, in process_search_term
    self.wait.until(EC.presence_of_all_elements_located((By.XPATH, "//li[@data-occludable-job-id]")))
    ~~~~~~~~~~~~~~~^^^^^^^^^^^^^^^^^^^^^^^^^^^^^^^^^^^^^^^^^^^^^^^^^^^^^^^^^^^^^^^^^^^^^^^^^^^^^^^^^^
  File "/home/wagle/garbageGold/.venv/lib/python3.13/site-packages/selenium/webdriver/support/wait.py", line 105, in until
    raise TimeoutException(message, screen, stacktrace)
selenium.common.exceptions.TimeoutException: Message: 


[2025-07-12 04:12:35] Processed 0 jobs for search term: "Front End Developer"
[2025-07-12 04:12:36] 
>>>> Now searching for ""Full Stack Developer"" <<<<

[2025-07-12 04:12:36] Setting search location as: "United States"
[2025-07-12 04:12:36] [ERROR] Unknown: Could not find element with xpath: './/input[@aria-label='City, state, or zip code'and not(@disabled)]'
Traceback (most recent call last):
  File "/home/wagle/garbageGold/app/linkedinBot/browser/clickers_and_finders.py", line 236, in try_xp
    element = driver.find_element(By.XPATH, xpath)
  File "/home/wagle/garbageGold/.venv/lib/python3.13/site-packages/selenium/webdriver/remote/webdriver.py", line 748, in find_element
    return self.execute(Command.FIND_ELEMENT, {"using": by, "value": value})["value"]
           ~~~~~~~~~~~~^^^^^^^^^^^^^^^^^^^^^^^^^^^^^^^^^^^^^^^^^^^^^^^^^^^^^
  File "/home/wagle/garbageGold/.venv/lib/python3.13/site-packages/selenium/webdriver/remote/webdriver.py", line 354, in execute
    self.error_handler.check_response(response)
    ~~~~~~~~~~~~~~~~~~~~~~~~~~~~~~~~~^^^^^^^^^^
  File "/home/wagle/garbageGold/.venv/lib/python3.13/site-packages/selenium/webdriver/remote/errorhandler.py", line 229, in check_response
    raise exception_class(message, screen, stacktrace)
selenium.common.exceptions.NoSuchElementException: Message: no such element: Unable to locate element: {"method":"xpath","selector":".//input[@aria-label='City, state, or zip code'and not(@disabled)]"}
  (Session info: chrome=138.0.7204.49); For documentation on this error, please visit: https://www.selenium.dev/documentation/webdriver/troubleshooting/errors#no-such-element-exception
Stacktrace:
#0 0x64eb81b7d23a <unknown>
#1 0x64eb81627ab0 <unknown>
#2 0x64eb816796f0 <unknown>
#3 0x64eb816798e1 <unknown>
#4 0x64eb816c7b94 <unknown>
#5 0x64eb8169f1cd <unknown>
#6 0x64eb816c4fee <unknown>
#7 0x64eb8169ef73 <unknown>
#8 0x64eb8166baeb <unknown>
#9 0x64eb8166c751 <unknown>
#10 0x64eb81b41b4b <unknown>
#11 0x64eb81b45929 <unknown>
#12 0x64eb81b28929 <unknown>
#13 0x64eb81b464e8 <unknown>
#14 0x64eb81b0d0df <unknown>
#15 0x64eb81b6a8e8 <unknown>
#16 0x64eb81b6aac6 <unknown>
#17 0x64eb81b7c556 <unknown>
#18 0x72fe2f494ac3 <unknown>


[2025-07-12 04:12:36] [ERROR] Unknown: Search Location input element was not provided!
NoneType: None

[2025-07-12 04:12:41] [ERROR] Unknown: Setting the preferences failed!
Traceback (most recent call last):
  File "/home/wagle/garbageGold/app/linkedinBot/job_filters/filters.py", line 23, in apply_filters
    wait.until(EC.presence_of_element_located((By.XPATH, '//button[normalize-space()="All filters"]'))).click()
    ~~~~~~~~~~^^^^^^^^^^^^^^^^^^^^^^^^^^^^^^^^^^^^^^^^^^^^^^^^^^^^^^^^^^^^^^^^^^^^^^^^^^^^^^^^^^^^^^^^^
  File "/home/wagle/garbageGold/.venv/lib/python3.13/site-packages/selenium/webdriver/support/wait.py", line 105, in until
    raise TimeoutException(message, screen, stacktrace)
selenium.common.exceptions.TimeoutException: Message: 
Stacktrace:
#0 0x64eb81b7d23a <unknown>
#1 0x64eb81627ab0 <unknown>
#2 0x64eb816796f0 <unknown>
#3 0x64eb816798e1 <unknown>
#4 0x64eb816c7b94 <unknown>
#5 0x64eb8169f1cd <unknown>
#6 0x64eb816c4fee <unknown>
#7 0x64eb8169ef73 <unknown>
#8 0x64eb8166baeb <unknown>
#9 0x64eb8166c751 <unknown>
#10 0x64eb81b41b4b <unknown>
#11 0x64eb81b45929 <unknown>
#12 0x64eb81b28929 <unknown>
#13 0x64eb81b464e8 <unknown>
#14 0x64eb81b0d0df <unknown>
#15 0x64eb81b6a8e8 <unknown>
#16 0x64eb81b6aac6 <unknown>
#17 0x64eb81b7c556 <unknown>
#18 0x72fe2f494ac3 <unknown>


[2025-07-12 04:12:47] Failed to process search term:
[2025-07-12 04:12:47] [ERROR] ('Connection aborted.', RemoteDisconnected('Remote end closed connection without response')): In process_search_term
Traceback (most recent call last):
  File "/home/wagle/garbageGold/.venv/lib/python3.13/site-packages/urllib3/connectionpool.py", line 789, in urlopen
    response = self._make_request(
        conn,
    ...<10 lines>...
        **response_kw,
    )
  File "/home/wagle/garbageGold/.venv/lib/python3.13/site-packages/urllib3/connectionpool.py", line 536, in _make_request
    response = conn.getresponse()
  File "/home/wagle/garbageGold/.venv/lib/python3.13/site-packages/urllib3/connection.py", line 507, in getresponse
    httplib_response = super().getresponse()
  File "/usr/lib/python3.13/http/client.py", line 1430, in getresponse
    response.begin()
    ~~~~~~~~~~~~~~^^
  File "/usr/lib/python3.13/http/client.py", line 331, in begin
    version, status, reason = self._read_status()
                              ~~~~~~~~~~~~~~~~~^^
  File "/usr/lib/python3.13/http/client.py", line 300, in _read_status
    raise RemoteDisconnected("Remote end closed connection without"
                             " response")
http.client.RemoteDisconnected: Remote end closed connection without response

During handling of the above exception, another exception occurred:

Traceback (most recent call last):
  File "/home/wagle/garbageGold/app/linkedinBot/linkedinRun.py", line 572, in process_search_term
    self.wait.until(EC.presence_of_all_elements_located((By.XPATH, "//li[@data-occludable-job-id]")))
    ~~~~~~~~~~~~~~~^^^^^^^^^^^^^^^^^^^^^^^^^^^^^^^^^^^^^^^^^^^^^^^^^^^^^^^^^^^^^^^^^^^^^^^^^^^^^^^^^^
  File "/home/wagle/garbageGold/.venv/lib/python3.13/site-packages/selenium/webdriver/support/wait.py", line 96, in until
    value = method(self._driver)
  File "/home/wagle/garbageGold/.venv/lib/python3.13/site-packages/selenium/webdriver/support/expected_conditions.py", line 191, in _predicate
    return driver.find_elements(*locator)
           ~~~~~~~~~~~~~~~~~~~~^^^^^^^^^^
  File "/home/wagle/garbageGold/.venv/lib/python3.13/site-packages/selenium/webdriver/remote/webdriver.py", line 778, in find_elements
    return self.execute(Command.FIND_ELEMENTS, {"using": by, "value": value})["value"] or []
           ~~~~~~~~~~~~^^^^^^^^^^^^^^^^^^^^^^^^^^^^^^^^^^^^^^^^^^^^^^^^^^^^^^
  File "/home/wagle/garbageGold/.venv/lib/python3.13/site-packages/selenium/webdriver/remote/webdriver.py", line 352, in execute
    response = self.command_executor.execute(driver_command, params)
  File "/home/wagle/garbageGold/.venv/lib/python3.13/site-packages/selenium/webdriver/remote/remote_connection.py", line 306, in execute
    return self._request(command_info[0], url, body=data)
           ~~~~~~~~~~~~~^^^^^^^^^^^^^^^^^^^^^^^^^^^^^^^^^
  File "/home/wagle/garbageGold/.venv/lib/python3.13/site-packages/selenium/webdriver/remote/remote_connection.py", line 326, in _request
    response = self._conn.request(method, url, body=body, headers=headers)
  File "/home/wagle/garbageGold/.venv/lib/python3.13/site-packages/urllib3/_request_methods.py", line 143, in request
    return self.request_encode_body(
           ~~~~~~~~~~~~~~~~~~~~~~~~^
        method, url, fields=fields, headers=headers, **urlopen_kw
        ^^^^^^^^^^^^^^^^^^^^^^^^^^^^^^^^^^^^^^^^^^^^^^^^^^^^^^^^^
    )
    ^
  File "/home/wagle/garbageGold/.venv/lib/python3.13/site-packages/urllib3/_request_methods.py", line 278, in request_encode_body
    return self.urlopen(method, url, **extra_kw)
           ~~~~~~~~~~~~^^^^^^^^^^^^^^^^^^^^^^^^^
  File "/home/wagle/garbageGold/.venv/lib/python3.13/site-packages/urllib3/poolmanager.py", line 443, in urlopen
    response = conn.urlopen(method, u.request_uri, **kw)
  File "/home/wagle/garbageGold/.venv/lib/python3.13/site-packages/urllib3/connectionpool.py", line 843, in urlopen
    retries = retries.increment(
        method, url, error=new_e, _pool=self, _stacktrace=sys.exc_info()[2]
    )
  File "/home/wagle/garbageGold/.venv/lib/python3.13/site-packages/urllib3/util/retry.py", line 474, in increment
    raise reraise(type(error), error, _stacktrace)
          ~~~~~~~^^^^^^^^^^^^^^^^^^^^^^^^^^^^^^^^^
  File "/home/wagle/garbageGold/.venv/lib/python3.13/site-packages/urllib3/util/util.py", line 38, in reraise
    raise value.with_traceback(tb)
  File "/home/wagle/garbageGold/.venv/lib/python3.13/site-packages/urllib3/connectionpool.py", line 789, in urlopen
    response = self._make_request(
        conn,
    ...<10 lines>...
        **response_kw,
    )
  File "/home/wagle/garbageGold/.venv/lib/python3.13/site-packages/urllib3/connectionpool.py", line 536, in _make_request
    response = conn.getresponse()
  File "/home/wagle/garbageGold/.venv/lib/python3.13/site-packages/urllib3/connection.py", line 507, in getresponse
    httplib_response = super().getresponse()
  File "/usr/lib/python3.13/http/client.py", line 1430, in getresponse
    response.begin()
    ~~~~~~~~~~~~~~^^
  File "/usr/lib/python3.13/http/client.py", line 331, in begin
    version, status, reason = self._read_status()
                              ~~~~~~~~~~~~~~~~~^^
  File "/usr/lib/python3.13/http/client.py", line 300, in _read_status
    raise RemoteDisconnected("Remote end closed connection without"
                             " response")
urllib3.exceptions.ProtocolError: ('Connection aborted.', RemoteDisconnected('Remote end closed connection without response'))

[2025-07-12 04:12:53] Processed 0 jobs for search term: "Full Stack Developer"
[2025-07-12 04:12:53] Error in continuous run:
[2025-07-12 04:12:53] [ERROR] HTTPConnectionPool(host='localhost', port=45831): Max retries exceeded with url: /session/a35241a78a0935b76a6fd49542484353/url (Caused by NewConnectionError('<urllib3.connection.HTTPConnection object at 0x73b02246b2f0>: Failed to establish a new connection: [Errno 111] Connection refused')): In run_continuous
Traceback (most recent call last):
  File "/home/wagle/garbageGold/.venv/lib/python3.13/site-packages/urllib3/connection.py", line 199, in _new_conn
    sock = connection.create_connection(
        (self._dns_host, self.port),
    ...<2 lines>...
        socket_options=self.socket_options,
    )
  File "/home/wagle/garbageGold/.venv/lib/python3.13/site-packages/urllib3/util/connection.py", line 85, in create_connection
    raise err
  File "/home/wagle/garbageGold/.venv/lib/python3.13/site-packages/urllib3/util/connection.py", line 73, in create_connection
    sock.connect(sa)
    ~~~~~~~~~~~~^^^^
ConnectionRefusedError: [Errno 111] Connection refused

The above exception was the direct cause of the following exception:

Traceback (most recent call last):
  File "/home/wagle/garbageGold/.venv/lib/python3.13/site-packages/urllib3/connectionpool.py", line 789, in urlopen
    response = self._make_request(
        conn,
    ...<10 lines>...
        **response_kw,
    )
  File "/home/wagle/garbageGold/.venv/lib/python3.13/site-packages/urllib3/connectionpool.py", line 495, in _make_request
    conn.request(
    ~~~~~~~~~~~~^
        method,
        ^^^^^^^
    ...<6 lines>...
        enforce_content_length=enforce_content_length,
        ^^^^^^^^^^^^^^^^^^^^^^^^^^^^^^^^^^^^^^^^^^^^^^
    )
    ^
  File "/home/wagle/garbageGold/.venv/lib/python3.13/site-packages/urllib3/connection.py", line 441, in request
    self.endheaders()
    ~~~~~~~~~~~~~~~^^
  File "/usr/lib/python3.13/http/client.py", line 1333, in endheaders
    self._send_output(message_body, encode_chunked=encode_chunked)
    ~~~~~~~~~~~~~~~~~^^^^^^^^^^^^^^^^^^^^^^^^^^^^^^^^^^^^^^^^^^^^^
  File "/usr/lib/python3.13/http/client.py", line 1093, in _send_output
    self.send(msg)
    ~~~~~~~~~^^^^^
  File "/usr/lib/python3.13/http/client.py", line 1037, in send
    self.connect()
    ~~~~~~~~~~~~^^
  File "/home/wagle/garbageGold/.venv/lib/python3.13/site-packages/urllib3/connection.py", line 279, in connect
    self.sock = self._new_conn()
                ~~~~~~~~~~~~~~^^
  File "/home/wagle/garbageGold/.venv/lib/python3.13/site-packages/urllib3/connection.py", line 214, in _new_conn
    raise NewConnectionError(
        self, f"Failed to establish a new connection: {e}"
    ) from e
urllib3.exceptions.NewConnectionError: <urllib3.connection.HTTPConnection object at 0x73b02246b2f0>: Failed to establish a new connection: [Errno 111] Connection refused

The above exception was the direct cause of the following exception:

Traceback (most recent call last):
  File "/home/wagle/garbageGold/app/linkedinBot/linkedinRun.py", line 690, in run_continuous
    processed = self.run_application_cycle(search_terms)
  File "/home/wagle/garbageGold/app/linkedinBot/linkedinRun.py", line 670, in run_application_cycle
    processed = self.process_search_term(search_term)
  File "/home/wagle/garbageGold/app/linkedinBot/linkedinRun.py", line 562, in process_search_term
    self.driver.get(f"https://www.linkedin.com/jobs/search/?keywords={search_term}")
    ~~~~~~~~~~~~~~~^^^^^^^^^^^^^^^^^^^^^^^^^^^^^^^^^^^^^^^^^^^^^^^^^^^^^^^^^^^^^^^^^
  File "/home/wagle/garbageGold/.venv/lib/python3.13/site-packages/selenium/webdriver/remote/webdriver.py", line 363, in get
    self.execute(Command.GET, {"url": url})
    ~~~~~~~~~~~~^^^^^^^^^^^^^^^^^^^^^^^^^^^
  File "/home/wagle/garbageGold/.venv/lib/python3.13/site-packages/selenium/webdriver/remote/webdriver.py", line 352, in execute
    response = self.command_executor.execute(driver_command, params)
  File "/home/wagle/garbageGold/.venv/lib/python3.13/site-packages/selenium/webdriver/remote/remote_connection.py", line 306, in execute
    return self._request(command_info[0], url, body=data)
           ~~~~~~~~~~~~~^^^^^^^^^^^^^^^^^^^^^^^^^^^^^^^^^
  File "/home/wagle/garbageGold/.venv/lib/python3.13/site-packages/selenium/webdriver/remote/remote_connection.py", line 326, in _request
    response = self._conn.request(method, url, body=body, headers=headers)
  File "/home/wagle/garbageGold/.venv/lib/python3.13/site-packages/urllib3/_request_methods.py", line 143, in request
    return self.request_encode_body(
           ~~~~~~~~~~~~~~~~~~~~~~~~^
        method, url, fields=fields, headers=headers, **urlopen_kw
        ^^^^^^^^^^^^^^^^^^^^^^^^^^^^^^^^^^^^^^^^^^^^^^^^^^^^^^^^^
    )
    ^
  File "/home/wagle/garbageGold/.venv/lib/python3.13/site-packages/urllib3/_request_methods.py", line 278, in request_encode_body
    return self.urlopen(method, url, **extra_kw)
           ~~~~~~~~~~~~^^^^^^^^^^^^^^^^^^^^^^^^^
  File "/home/wagle/garbageGold/.venv/lib/python3.13/site-packages/urllib3/poolmanager.py", line 443, in urlopen
    response = conn.urlopen(method, u.request_uri, **kw)
  File "/home/wagle/garbageGold/.venv/lib/python3.13/site-packages/urllib3/connectionpool.py", line 873, in urlopen
    return self.urlopen(
           ~~~~~~~~~~~~^
        method,
        ^^^^^^^
    ...<13 lines>...
        **response_kw,
        ^^^^^^^^^^^^^^
    )
    ^
  File "/home/wagle/garbageGold/.venv/lib/python3.13/site-packages/urllib3/connectionpool.py", line 873, in urlopen
    return self.urlopen(
           ~~~~~~~~~~~~^
        method,
        ^^^^^^^
    ...<13 lines>...
        **response_kw,
        ^^^^^^^^^^^^^^
    )
    ^
  File "/home/wagle/garbageGold/.venv/lib/python3.13/site-packages/urllib3/connectionpool.py", line 873, in urlopen
    return self.urlopen(
           ~~~~~~~~~~~~^
        method,
        ^^^^^^^
    ...<13 lines>...
        **response_kw,
        ^^^^^^^^^^^^^^
    )
    ^
  File "/home/wagle/garbageGold/.venv/lib/python3.13/site-packages/urllib3/connectionpool.py", line 843, in urlopen
    retries = retries.increment(
        method, url, error=new_e, _pool=self, _stacktrace=sys.exc_info()[2]
    )
  File "/home/wagle/garbageGold/.venv/lib/python3.13/site-packages/urllib3/util/retry.py", line 519, in increment
    raise MaxRetryError(_pool, url, reason) from reason  # type: ignore[arg-type]
    ^^^^^^^^^^^^^^^^^^^^^^^^^^^^^^^^^^^^^^^^^^^^^^^^^^^
urllib3.exceptions.MaxRetryError: HTTPConnectionPool(host='localhost', port=45831): Max retries exceeded with url: /session/a35241a78a0935b76a6fd49542484353/url (Caused by NewConnectionError('<urllib3.connection.HTTPConnection object at 0x73b02246b2f0>: Failed to establish a new connection: [Errno 111] Connection refused'))

[2025-07-12 04:12:53] 
============================================================
[2025-07-12 04:12:53] FINAL STATISTICS
[2025-07-12 04:12:53] ============================================================
[2025-07-12 04:12:53] Total runs:                     1
[2025-07-12 04:12:53] Jobs Easy Applied:              0
[2025-07-12 04:12:53] External job links collected:   0
[2025-07-12 04:12:53]                               ----------
[2025-07-12 04:12:53] Total applied or collected:     0
[2025-07-12 04:12:53] 
Failed jobs:                    0
[2025-07-12 04:12:53] Irrelevant jobs skipped:        0
[2025-07-12 04:12:53] 
The only impossible journey is the one you never begin. - Tony Robbins

Best regards : )
[2025-07-12 04:12:56] Closing OpenAI client...
[2025-07-12 04:12:56] OpenAI client closed successfully
[2025-07-12 04:12:56] Closed deepseek AI client.
[2025-07-12 04:12:56] Browser closed successfully
